Workbook

Sheet Kangatang

Sheet Jan
A1: 일일 생산량 현황
B3: 12월31일 | C3: 절포 | D3: 생산량 | E3: LOT | F3: LOT | G3: LOT | H3: LOT | I3: LOT | J3: LOT | K3: LOT | L3: LOT | M3: LOT | N3: LOT | O3: LOT | P3: LOT | Q3: LOT | R3: LOT | S3: LOT | T3: LOT | U3: LOT | V3: LOT | W3: LOT | X3: LOT | Y3: LOT | Z3: LOT | AA3: LOT | AB3: LOT | AC3: LOT | AD3: LOT | AE3: LOT | AF3: 1월2일 | AG3: 절포 | AH3: 생산량 | AI3: 1월3일 | AJ3: 절포 | AK3: 생산량 | AL3: 1월4일 | AM3: 절포 | AN3: 생산량 | AO3: 1월5일 | AP3: 절포 | AQ3: 생산량 | AR3: 1월6일 | AS3: 절포 | AT3: 생산량 | AU3: 1월7일 | AV3: 절포 | AW3: 생산량 | AX3: 1월8일 | AY3: 절포 | AZ3: 생산량 | BA3: 1월9일 | BB3: 절포 | BC3: 생산량 | BD3: 1월10일 | BE3: 절포 | BF3: 생산량 | BG3: 1월11일 | BH3: 절포 | BI3: 생산량 | BJ3: 1월12일 | BK3: 절포 | BL3: 생산량 | BM3: 1월13일 | BN3: 절포 | BO3: 생산량 | BP3: 1월14일 | BQ3: 절포 | BR3: 생산량 | BS3: 1월15일 | BT3: 절포 | BU3: 생산량 | BV3: 1월16일 | BW3: 절포 | BX3: 생산량 | BY3: 1월17일 | BZ3: 절포 | CA3: 생산량 | CB3: 1월18일 | CC3: 절포 | CD3: 생산량 | CE3: 1월19일 | CF3: 절포 | CG3: 생산량 | CH3: 1월20일 | CI3: 절포 | CJ3: 생산량 | CK3: 1월21일 | CL3: 절포 | CM3: 생산량 | CN3: 1월22일 | CO3: 절포 | CP3: 생산량 | CQ3: 1월23일 | CR3: 절포 | CS3: 생산량 | CT3: 1월24일 | CU3: 절포 | CV3: 생산량 | CW3: 1월25일 | CX3: 절포 | CY3: 생산량 | CZ3: 1월26일 | DA3: 절포 | DB3: 생산량 | DC3: 1월27일 | DD3: 절포 | DE3: 생산량 | DF3: 1월28일 | DG3: 절포 | DH3: 생산량 | DI3: 1월29일 | DJ3: 절포 | DK3: 생산량 | DL3: 1월30일 | DM3: 절포 | DN3: 생산량 | DO3: 1월31일 | DP3: 절포 | DQ3: 생산량
A4: 호기 | E4: 46022 | F4: 46024 | G4: 46025 | H4: 46027 | I4: 46028 | J4: 46029 | K4: 46030 | L4: 46031 | M4: 46032 | N4: 46034 | O4: 46035 | P4: 46036 | Q4: 46037 | R4: 46038 | S4: 46039 | T4: 46041 | U4: 46042 | V4: 46043 | W4: 46044 | X4: 46045 | Y4: 46046 | Z4: 46048 | AA4: 46049 | AB4: 46050 | AC4: 46051 | AD4: 46052 | AE4: 46053
A5: 1 | B5: 308 | C5: 1279 | D5: 367 | E5: 011-3 | F5: 011-3 | G5: ACZ07 | H5: ACZ07 | I5: ACZ07 | J5: ACZ07 | K5: ACZ07 | L5: ACZ07 | M5: ACZ07 | N5: 011-3 | O5: 011-3 | P5: 011-3 | Q5: 011-3 | R5: 011-3 | S5: 011-3 | T5: 011-3 | U5: 011-3 | V5: 011-3 | W5: 011-3 | X5: 011-3 | Y5: 011-3 | Z5: 011-3 | AA5: 011-3 | AB5: 011-3 | AC5: 011-3 | AD5: 011-3 | AE5: 011-3 | AF5: 685 | AH5: =AG5+AF5-B5 -> 377 | AI5: 246 | AJ5: 690 | AK5: =AJ5+AI5-AF5 -> 251 | AO5: 566 | AQ5: =AP5+AO5-AI5 -> 320 | AR5: 285 | AS5: 610 | AT5: =AS5+AR5-AO5 -> 329 | AU5: 25 | AV5: 610 | AW5: =AV5+AU5-AR5 -> 350 | AX5: 377 | AZ5: =AY5+AX5-AU5 -> 352 | BA5: 133 | BB5: 600 | BC5: =BB5+BA5-AX5 -> 356 | BD5: 0 | BE5: 462 | BF5: =BE5+BD5-BA5 -> 329 | BJ5: 263 | BL5: =BK5+BJ5-BD5 -> 263 | BM5: 618 | BO5: =BN5+BM5-BJ5 -> 355 | BP5: 233 | BQ5: 750 | BR5: =BQ5+BP5-BM5 -> 365 | BS5: 96 | BT5: 479 | BU5: =BT5+BS5-BP5 -> 342 | BV5: 448 | BX5: =BW5+BV5-BS5 -> 352 | BY5: 783 | CA5: =BZ5+BY5-BV5 -> 335 | CE5: 1134 | CG5: =CF5+CE5-BY5 -> 351 | CH5: 1489 | CJ5: =CI5+CH5-CE5 -> 355 | CK5: 277 | CL5: 1560 | CM5: =CL5+CK5-CH5 -> 348 | CN5: 637 | CP5: =CO5+CN5-CK5 -> 360 | CQ5: 998 | CS5: =CR5+CQ5-CN5 -> 361 | CT5: 1340 | CV5: =CU5+CT5-CQ5 -> 342 | CZ5: 136 | DA5: 1560 | DB5: =DA5+CZ5-CT5 -> 356 | DC5: 481 | DE5: =DD5+DC5-CZ5 -> 345 | DF5: 840 | DH5: =DG5+DF5-DC5 -> 359 | DI5: 1200 | DK5: =DJ5+DI5-DF5 -> 360 | DL5: 1561 | DN5: =DM5+DL5-DI5 -> 361 | DO5: 333 | DP5: 1565 | DQ5: =DP5+DO5-DL5 -> 337
A6: 2 | B6: 607 | D6: 373 | E6: SC-1020 | F6: SC-1020 | G6: SC-1020 | H6: SC-1004 | I6: SC-1004 | J6: SC-1004 | K6: SC-1004 | L6: SC-1004 | M6: SC-1004 | N6: SC-1004 | O6: SC-1004 | P6: SC-1004 | Q6: SC-1004 | R6: SC-1004 | S6: SC-1004 | T6: SC-1004 | U6: SC-1004 | V6: SC-1004 | W6: SC-1004 | X6: SC-1004 | Y6: SC-1004 | Z6: SC-1004 | AA6: SC-1004 | AB6: SC-1004 | AC6: SC-1004 | AD6: SC-1004 | AE6: SC-1004 | AF6: 978 | AH6: =AG6+AF6-B6 -> 371 | AI6: 0 | AJ6: 1273 | AK6: =AJ6+AI6-AF6 -> 295 | AO6: 159 | AQ6: =AP6+AO6-AI6 -> 159 | AR6: 402 | AT6: =AS6+AR6-AO6 -> 243 | AU6: 641 | AW6: =AV6+AU6-AR6 -> 239 | AX6: 180 | AY6: 702 | AZ6: =AY6+AX6-AU6 -> 241 | BA6: 409 | BC6: =BB6+BA6-AX6 -> 229 | BD6: 633 | BF6: =BE6+BD6-BA6 -> 224 | BJ6: 865 | BL6: =BK6+BJ6-BD6 -> 232 | BM6: 1096 | BO6: =BN6+BM6-BJ6 -> 231 | BP6: 1330 | BR6: =BQ6+BP6-BM6 -> 234 | BS6: 1563 | BU6: =BT6+BS6-BP6 -> 233 | BV6: 1787 | BX6: =BW6+BV6-BS6 -> 224 | BY6: 6 | BZ6: 1995 | CA6: =BZ6+BY6-BV6 -> 214 | CE6: 228 | CG6: =CF6+CE6-BY6 -> 222 | CH6: 462 | CJ6: =CI6+CH6-CE6 -> 234 | CK6: 691 | CM6: =CL6+CK6-CH6 -> 229 | CN6: 924 | CP6: =CO6+CN6-CK6 -> 233 | CQ6: 1150 | CS6: =CR6+CQ6-CN6 -> 226 | CT6: 1375 | CV6: =CU6+CT6-CQ6 -> 225 | CZ6: 1609 | DB6: =DA6+CZ6-CT6 -> 234 | DC6: 1841 | DE6: =DD6+DC6-CZ6 -> 232 | DF6: 73 | DG6: 2000 | DH6: =DG6+DF6-DC6 -> 232 | DI6: 305 | DK6: =DJ6+DI6-DF6 -> 232 | DL6: 536 | DN6: =DM6+DL6-DI6 -> 231 | DO6: 751 | DQ6: =DP6+DO6-DL6 -> 215
A7: 3 | B7: 1159 | D7: 369 | E7: SC-1020 | F7: SC-1020 | G7: ACZ07 | H7: ACZ07 | I7: ACZ07 | J7: ACZ07 | K7: ACZ07 | L7: ACZ07 | M7: ACZ07 | N7: ACZ07 | O7: ACZ07 | P7: ACZ07 | Q7: SC-1020 | R7: SC-1020 | S7: SC-1020 | T7: SC-1020 | U7: SC-1020 | V7: SC-1020 | W7: SC-1020 | X7: SC-1020 | Y7: SC-1020 | Z7: SC-1020 | AA7: SC-1020 | AB7: SC-1020 | AC7: SC-1020 | AD7: SC-1020 | AE7: SC-1020 | AF7: 1534 | AH7: =AG7+AF7-B7 -> 375 | AI7: 273 | AJ7: 1539 | AK7: =AJ7+AI7-AF7 -> 278 | AO7: 10 | AP7: 600 | AQ7: =AP7+AO7-AI7 -> 337 | AR7: 346 | AT7: =AS7+AR7-AO7 -> 336 | AU7: 80 | AV7: 600 | AW7: =AV7+AU7-AR7 -> 334 | AX7: 432 | AZ7: =AY7+AX7-AU7 -> 352 | BA7: 177 | BB7: 600 | BC7: =BB7+BA7-AX7 -> 345 | BD7: 518 | BF7: =BE7+BD7-BA7 -> 341 | BJ7: 270 | BK7: 600 | BL7: =BK7+BJ7-BD7 -> 352 | BM7: 0 | BN7: 608 | BO7: =BN7+BM7-BJ7 -> 338 | BP7: 0 | BR7: =BQ7+BP7-BM7 -> 0 | BS7: 0 | BU7: =BT7+BS7-BP7 -> 0 | BV7: 0 | BX7: =BW7+BV7-BS7 -> 0 | BY7: 0 | CA7: =BZ7+BY7-BV7 -> 0 | CE7: 0 | CG7: =CF7+CE7-BY7 -> 0 | CH7: 310 | CJ7: =CI7+CH7-CE7 -> 310 | CK7: 695 | CM7: =CL7+CK7-CH7 -> 385 | CN7: 1077 | CP7: =CO7+CN7-CK7 -> 382 | CQ7: 1445 | CS7: =CR7+CQ7-CN7 -> 368 | CT7: 232 | CU7: 1560 | CV7: =CU7+CT7-CQ7 -> 347 | CZ7: 605 | DB7: =DA7+CZ7-CT7 -> 373 | DC7: 971 | DE7: =DD7+DC7-CZ7 -> 366 | DF7: 1333 | DH7: =DG7+DF7-DC7 -> 362 | DI7: 124 | DJ7: 1560 | DK7: =DJ7+DI7-DF7 -> 351 | DL7: 492 | DN7: =DM7+DL7-DI7 -> 368 | DO7: 0 | DP7: 760 | DQ7: =DP7+DO7-DL7 -> 268
A8: 4 | B8: 556 | D8: 351 | E8: SC-1020 | F8: SC-1020 | G8: SC-1020 | H8: SC-1020 | I8: SC-1020 | J8: SC-1020 | K8: SC-1020 | L8: SC-1020 | M8: SC-1020 | N8: SC-1020 | O8: SC-1020 | P8: SC-1020 | Q8: SC-1020 | R8: SC-1020 | S8: SC-1020 | T8: SC-1020 | U8: SC-1020 | V8: SC-1020 | W8: SC-1020 | X8: SC-1020 | Y8: SC-1020 | Z8: SC-1020 | AA8: SC-1020 | AB8: SC-1020 | AC8: SC-1020 | AD8: SC-1020 | AE8: SC-1020 | AF8: 337 | AG8: 586 | AH8: =AG8+AF8-B8 -> 367 | AI8: 683 | AK8: =AJ8+AI8-AF8 -> 346 | AO8: 1045 | AQ8: =AP8+AO8-AI8 -> 362 | AR8: 1415 | AT8: =AS8+AR8-AO8 -> 370 | AU8: 212 | AV8: 1560 | AW8: =AV8+AU8-AR8 -> 357 | AX8: 577 | AZ8: =AY8+AX8-AU8 -> 365 | BA8: 946 | BC8: =BB8+BA8-AX8 -> 369 | BD8: 1306 | BF8: =BE8+BD8-BA8 -> 360 | BJ8: 121 | BK8: 1560 | BL8: =BK8+BJ8-BD8 -> 375 | BM8: 162 | BN8: 323 | BO8: =BN8+BM8-BJ8 -> 364 | BP8: 537 | BR8: =BQ8+BP8-BM8 -> 375 | BS8: 907 | BU8: =BT8+BS8-BP8 -> 370 | BV8: 1268 | BX8: =BW8+BV8-BS8 -> 361 | BY8: 109 | BZ8: 1503 | CA8: =BZ8+BY8-BV8 -> 344 | CE8: 470 | CG8: =CF8+CE8-BY8 -> 361 | CH8: 543 | CJ8: =CI8+CH8-CE8 -> 73 | CK8: 543 | CM8: =CL8+CK8-CH8 -> 0 | CN8: 0 | CO8: 771 | CP8: =CO8+CN8-CK8 -> 228 | CQ8: 279 | CS8: =CR8+CQ8-CN8 -> 279 | CT8: 635 | CV8: =CU8+CT8-CQ8 -> 356 | CZ8: 1006 | DB8: =DA8+CZ8-CT8 -> 371 | DC8: 1374 | DE8: =DD8+DC8-CZ8 -> 368 | DF8: 176 | DG8: 1560 | DH8: =DG8+DF8-DC8 -> 362 | DI8: 534 | DK8: =DJ8+DI8-DF8 -> 358 | DL8: 891 | DN8: =DM8+DL8-DI8 -> 357 | DO8: 1227 | DQ8: =DP8+DO8-DL8 -> 336
A9: 5 | B9: 992 | D9: 367 | E9: SC-1020 | F9: SC-1020 | G9: ACZ07 | H9: ACZ07 | I9: ACZ07 | J9: ACZ07 | K9: ACZ07 | L9: ACZ07 | M9: ACZ07 | N9: ACZ07 | O9: ACZ07 | P9: ACZ07 | Q9: SC-1020 | R9: SC-1020 | S9: SC-1020 | T9: SC-1020 | U9: SC-1020 | V9: SC-1020 | W9: SC-1020 | X9: SC-1020 | Y9: SC-1020 | Z9: SC-1020 | AA9: SC-1020 | AB9: SC-1020 | AC9: SC-1020 | AD9: SC-1020 | AE9: SC-1020 | AF9: 1368 | AH9: =AG9+AF9-B9 -> 376 | AI9: 266 | AJ9: 1373 | AK9: =AJ9+AI9-AF9 -> 271 | AO9: 10 | AP9: 600 | AQ9: =AP9+AO9-AI9 -> 344 | AR9: 361 | AT9: =AS9+AR9-AO9 -> 351 | AU9: 98 | AV9: 600 | AW9: =AV9+AU9-AR9 -> 337 | AX9: 456 | AZ9: =AY9+AX9-AU9 -> 358 | BA9: 208 | BB9: 600 | BC9: =BB9+BA9-AX9 -> 352 | BD9: 548 | BF9: =BE9+BD9-BA9 -> 340 | BJ9: 298 | BK9: 600 | BL9: =BK9+BJ9-BD9 -> 350 | BM9: 629 | BO9: =BN9+BM9-BJ9 -> 331 | BP9: 0 | BQ9: 629 | BR9: =BQ9+BP9-BM9 -> 0 | BS9: 0 | BU9: =BT9+BS9-BP9 -> 0 | BV9: 0 | BX9: =BW9+BV9-BS9 -> 0 | BY9: 0 | CA9: =BZ9+BY9-BV9 -> 0 | CE9: 0 | CG9: =CF9+CE9-BY9 -> 0 | CH9: 306 | CJ9: =CI9+CH9-CE9 -> 306 | CK9: 664 | CM9: =CL9+CK9-CH9 -> 358 | CN9: 1039 | CP9: =CO9+CN9-CK9 -> 375 | CQ9: 1400 | CS9: =CR9+CQ9-CN9 -> 361 | CT9: 182 | CU9: 1560 | CV9: =CU9+CT9-CQ9 -> 342 | CZ9: 549 | DB9: =DA9+CZ9-CT9 -> 367 | DC9: 301 | DD9: 600 | DE9: =DD9+DC9-CZ9 -> 352 | DF9: 655 | DH9: =DG9+DF9-DC9 -> 354 | DI9: 1021 | DK9: =DJ9+DI9-DF9 -> 366 | DL9: 1389 | DN9: =DM9+DL9-DI9 -> 368 | DO9: 162 | DP9: 1560 | DQ9: =DP9+DO9-DL9 -> 333
A10: 6 | B10: 51 | C10: 1561 | D10: 375 | E10: 011-3 | F10: 011-3 | G10: 011-3 | H10: 011-3 | I10: 011-3 | J10: 011-3 | K10: 011-3 | L10: 011-3 | M10: 011-3 | N10: 011-3 | O10: 011-3 | P10: 011-3 | Q10: 011-3 | R10: 011-3 | S10: SC-1020 | T10: SC-1020 | U10: SC-1020 | V10: SC-1020 | W10: SC-1020 | X10: SC-1020 | Y10: SC-1020 | Z10: SC-1020 | AA10: SC-1020 | AB10: SC-1020 | AC10: SC-1020 | AD10: SC-1020 | AE10: SC-1020 | AF10: 425 | AH10: =AG10+AF10-B10 -> 374 | AI10: 785 | AK10: =AJ10+AI10-AF10 -> 360 | AO10: 1160 | AQ10: =AP10+AO10-AI10 -> 375 | AR10: 1538 | AT10: =AS10+AR10-AO10 -> 378 | AU10: 349 | AV10: 1560 | AW10: =AV10+AU10-AR10 -> 371 | AX10: 727 | AZ10: =AY10+AX10-AU10 -> 378 | BA10: 1097 | BC10: =BB10+BA10-AX10 -> 370 | BD10: 1455 | BF10: =BE10+BD10-BA10 -> 358 | BJ10: 265 | BK10: 1560 | BL10: =BK10+BJ10-BD10 -> 370 | BM10: 635 | BO10: =BN10+BM10-BJ10 -> 370 | BP10: 1010 | BR10: =BQ10+BP10-BM10 -> 375 | BS10: 1382 | BU10: =BT10+BS10-BP10 -> 372 | BV10: 0 | BW10: 1443 | BX10: =BW10+BV10-BS10 -> 61 | BY10: 0 | CA10: =BZ10+BY10-BV10 -> 0 | CE10: 0 | CG10: =CF10+CE10-BY10 -> 0 | CH10: 285 | CJ10: =CI10+CH10-CE10 -> 285 | CK10: 645 | CM10: =CL10+CK10-CH10 -> 360 | CN10: 1022 | CP10: =CO10+CN10-CK10 -> 377 | CQ10: 1392 | CS10: =CR10+CQ10-CN10 -> 370 | CT10: 184 | CU10: 1560 | CV10: =CU10+CT10-CQ10 -> 352 | CZ10: 556 | DB10: =DA10+CZ10-CT10 -> 372 | DC10: 916 | DE10: =DD10+DC10-CZ10 -> 360 | DF10: 1284 | DH10: =DG10+DF10-DC10 -> 368 | DI10: 88 | DJ10: 1560 | DK10: =DJ10+DI10-DF10 -> 364 | DL10: 454 | DN10: =DM10+DL10-DI10 -> 366 | DO10: 792 | DQ10: =DP10+DO10-DL10 -> 338
A11: 7 | B11: 223 | C11: 1560 | D11: 368 | E11: 011-3 | F11: 011-3 | G11: ACZ07 | H11: ACZ07 | I11: ACZ07 | J11: ACZ07 | K11: ACZ07 | L11: ACZ07 | M11: ACZ07 | N11: ACZ07 | O11: ACZ07 | P11: ACZ07 | Q11: SC-1020 | R11: SC-1020 | S11: SC-1020 | T11: SC-1020 | U11: SC-1020 | V11: SC-1020 | W11: SC-1020 | X11: SC-1020 | Y11: SC-1020 | Z11: SC-1020 | AA11: SC-1020 | AB11: SC-1020 | AC11: SC-1020 | AD11: SC-1020 | AE11: SC-1020 | AF11: 604 | AH11: =AG11+AF11-B11 -> 381 | AI11: 250 | AJ11: 609 | AK11: =AJ11+AI11-AF11 -> 255 | AO11: 595 | AQ11: =AP11+AO11-AI11 -> 345 | AR11: 343 | AS11: 600 | AT11: =AS11+AR11-AO11 -> 348 | AU11: 78 | AV11: 600 | AW11: =AV11+AU11-AR11 -> 335 | AX11: 429 | AZ11: =AY11+AX11-AU11 -> 351 | BA11: 178 | BB11: 600 | BC11: =BB11+BA11-AX11 -> 349 | BD11: 509 | BF11: =BE11+BD11-BA11 -> 331 | BJ11: 250 | BK11: 600 | BL11: =BK11+BJ11-BD11 -> 341 | BM11: 590 | BO11: =BN11+BM11-BJ11 -> 340 | BP11: 0 | BQ11: 629 | BR11: =BQ11+BP11-BM11 -> 39 | BS11: 0 | BU11: =BT11+BS11-BP11 -> 0 | BV11: 0 | BX11: =BW11+BV11-BS11 -> 0 | BY11: 0 | CA11: =BZ11+BY11-BV11 -> 0 | CE11: 0 | CG11: =CF11+CE11-BY11 -> 0 | CH11: 256 | CJ11: =CI11+CH11-CE11 -> 256 | CK11: 609 | CM11: =CL11+CK11-CH11 -> 353 | CN11: 967 | CP11: =CO11+CN11-CK11 -> 358 | CQ11: 1329 | CS11: =CR11+CQ11-CN11 -> 362 | CT11: 111 | CU11: 1560 | CV11: =CU11+CT11-CQ11 -> 342 | CZ11: 461 | DB11: =DA11+CZ11-CT11 -> 350 | DC11: 813 | DE11: =DD11+DC11-CZ11 -> 352 | DF11: 1173 | DH11: =DG11+DF11-DC11 -> 360 | DI11: 1533 | DK11: =DJ11+DI11-DF11 -> 360 | DL11: 352 | DM11: 1545 | DN11: =DM11+DL11-DI11 -> 364 | DO11: 685 | DQ11: =DP11+DO11-DL11 -> 333
A12: 8 | B12: 1007 | D12: 370 | E12: SC-1020 | F12: SC-1020 | G12: SC-1020 | H12: SC-1004 | I12: SC-1004 | J12: SC-1004 | K12: SC-1004 | L12: SC-1004 | M12: SC-1004 | N12: SC-1004 | O12: SC-1004 | P12: SC-1004 | Q12: SC-1004 | R12: SC-1004 | S12: SC-1004 | T12: SC-1004 | U12: SC-1004 | V12: SC-1004 | W12: SC-1004 | X12: SC-1004 | Y12: SC-1004 | Z12: SC-1004 | AA12: SC-1004 | AB12: SC-1004 | AC12: SC-1004 | AD12: SC-1004 | AE12: SC-1004 | AF12: 1384 | AH12: =AG12+AF12-B12 -> 377 | AI12: 0 | AJ12: 1475 | AK12: =AJ12+AI12-AF12 -> 91 | AO12: 163 | AQ12: =AP12+AO12-AI12 -> 163 | AR12: 404 | AT12: =AS12+AR12-AO12 -> 241 | AU12: 638 | AW12: =AV12+AU12-AR12 -> 234 | AX12: 875 | AZ12: =AY12+AX12-AU12 -> 237 | BA12: 1106 | BC12: =BB12+BA12-AX12 -> 231 | BD12: 1330 | BF12: =BE12+BD12-BA12 -> 224 | BJ12: 1563 | BL12: =BK12+BJ12-BD12 -> 233 | BM12: 1794 | BO12: =BN12+BM12-BJ12 -> 231 | BP12: 26 | BQ12: 2000 | BR12: =BQ12+BP12-BM12 -> 232 | BS12: 249 | BU12: =BT12+BS12-BP12 -> 223 | BV12: 480 | BX12: =BW12+BV12-BS12 -> 231 | BY12: 7 | BZ12: 690 | CA12: =BZ12+BY12-BV12 -> 217 | CE12: 239 | CG12: =CF12+CE12-BY12 -> 232 | CH12: 473 | CJ12: =CI12+CH12-CE12 -> 234 | CK12: 706 | CM12: =CL12+CK12-CH12 -> 233 | CN12: 940 | CP12: =CO12+CN12-CK12 -> 234 | CQ12: 1172 | CS12: =CR12+CQ12-CN12 -> 232 | CT12: 1390 | CV12: =CU12+CT12-CQ12 -> 218 | CZ12: 1621 | DB12: =DA12+CZ12-CT12 -> 231 | DC12: 1848 | DE12: =DD12+DC12-CZ12 -> 227 | DF12: 75 | DG12: 2000 | DH12: =DG12+DF12-DC12 -> 227 | DI12: 302 | DK12: =DJ12+DI12-DF12 -> 227 | DL12: 531 | DN12: =DM12+DL12-DI12 -> 229 | DO12: 742 | DQ12: =DP12+DO12-DL12 -> 211
A13: 9 | B13: 313 | D13: 313 | E13: SC-1020 | F13: SC-1020 | G13: ACZ07 | H13: ACZ07 | I13: ACZ07 | J13: ACZ07 | K13: ACZ07 | L13: ACZ07 | M13: ACZ07 | N13: ACZ07 | O13: ACZ07 | P13: ACZ07 | Q13: SC-1020 | R13: SC-1020 | S13: SC-1020 | T13: SC-1020 | U13: SC-1020 | V13: SC-1020 | W13: SC-1020 | X13: SC-1020 | Y13: SC-1020 | Z13: SC-1020 | AA13: SC-1020 | AB13: SC-1020 | AC13: SC-1020 | AD13: SC-1020 | AE13: SC-1020 | AF13: 687 | AH13: =AG13+AF13-B13 -> 374 | AI13: 177 | AJ13: 692 | AK13: =AJ13+AI13-AF13 -> 182 | AO13: 506 | AQ13: =AP13+AO13-AI13 -> 329 | AR13: 243 | AS13: 600 | AT13: =AS13+AR13-AO13 -> 337 | AU13: 594 | AW13: =AV13+AU13-AR13 -> 351 | AX13: 343 | AY13: 600 | AZ13: =AY13+AX13-AU13 -> 349 | BA13: 95 | BB13: 600 | BC13: =BB13+BA13-AX13 -> 352 | BD13: 435 | BF13: =BE13+BD13-BA13 -> 340 | BJ13: 188 | BK13: 600 | BL13: =BK13+BJ13-BD13 -> 353 | BM13: 535 | BO13: =BN13+BM13-BJ13 -> 347 | BP13: 0 | BQ13: 635 | BR13: =BQ13+BP13-BM13 -> 100 | BS13: 0 | BU13: =BT13+BS13-BP13 -> 0 | BV13: 0 | BX13: =BW13+BV13-BS13 -> 0 | BY13: 0 | CA13: =BZ13+BY13-BV13 -> 0 | CE13: 0 | CG13: =CF13+CE13-BY13 -> 0 | CH13: 273 | CJ13: =CI13+CH13-CE13 -> 273 | CK13: 647 | CM13: =CL13+CK13-CH13 -> 374 | CN13: 1025 | CP13: =CO13+CN13-CK13 -> 378 | CQ13: 1400 | CS13: =CR13+CQ13-CN13 -> 375 | CT13: 35 | CU13: =1560+151 -> 1711 | CV13: =CU13+CT13-CQ13 -> 346 | CZ13: 413 | DB13: =DA13+CZ13-CT13 -> 378 | DC13: 787 | DE13: =DD13+DC13-CZ13 -> 374 | DF13: 35 | DG13: =790+275 -> 1065 | DH13: =DG13+DF13-DC13 -> 313 | DI13: 276 | DJ13: 128 | DK13: =DJ13+DI13-DF13 -> 369 | DL13: 60 | DM13: 569 | DN13: =DM13+DL13-DI13 -> 353 | DO13: 403 | DQ13: =DP13+DO13-DL13 -> 343
A14: 10 | B14: 709 | D14: 362 | E14: SC-1020 | F14: SC-1020 | G14: SC-1020 | H14: SC-1020 | I14: SC-1020 | J14: SC-1020 | K14: SC-1020 | L14: SC-1020 | M14: SC-1020 | N14: SC-1020 | O14: SC-1020 | P14: SC-1020 | Q14: SC-1020 | R14: SC-1020 | S14: SC-1020 | T14: SC-1020 | U14: SC-1020 | V14: SC-1020 | W14: SC-1020 | X14: SC-1020 | Y14: SC-1020 | Z14: SC-1020 | AA14: SC-1020 | AB14: SC-1020 | AC14: SC-1020 | AD14: SC-1020 | AE14: SC-1020 | AF14: 1092 | AH14: =AG14+AF14-B14 -> 383 | AI14: 1446 | AK14: =AJ14+AI14-AF14 -> 354 | AO14: 255 | AP14: 1561 | AQ14: =AP14+AO14-AI14 -> 370 | AR14: 627 | AT14: =AS14+AR14-AO14 -> 372 | AU14: 991 | AW14: =AV14+AU14-AR14 -> 364 | AX14: 1186 | AZ14: =AY14+AX14-AU14 -> 195 | BA14: 0 | BB14: 1388 | BC14: =BB14+BA14-AX14 -> 202 | BD14: 0 | BF14: =BE14+BD14-BA14 -> 0 | BJ14: 0 | BL14: =BK14+BJ14-BD14 -> 0 | BM14: 0 | BO14: =BN14+BM14-BJ14 -> 0 | BP14: 0 | BR14: =BQ14+BP14-BM14 -> 0 | BS14: 0 | BU14: =BT14+BS14-BP14 -> 0 | BV14: 0 | BX14: =BW14+BV14-BS14 -> 0 | BY14: 0 | CA14: =BZ14+BY14-BV14 -> 0 | CE14: 0 | CG14: =CF14+CE14-BY14 -> 0 | CH14: 279 | CJ14: =CI14+CH14-CE14 -> 279 | CK14: 256 | CL14: 373 | CM14: =CL14+CK14-CH14 -> 350 | CN14: 621 | CP14: =CO14+CN14-CK14 -> 365 | CQ14: 986 | CS14: =CR14+CQ14-CN14 -> 365 | CT14: 1328 | CV14: =CU14+CT14-CQ14 -> 342 | CZ14: 129 | DA14: 1560 | DB14: =DA14+CZ14-CT14 -> 361 | DC14: 493 | DE14: =DD14+DC14-CZ14 -> 364 | DF14: 862 | DH14: =DG14+DF14-DC14 -> 369 | DI14: 1227 | DK14: =DJ14+DI14-DF14 -> 365 | DL14: 32 | DM14: 1561 | DN14: =DM14+DL14-DI14 -> 366 | DO14: 372 | DQ14: =DP14+DO14-DL14 -> 340
A15: 11 | B15: 644 | D15: 373 | E15: SC-1020 | F15: SC-1020 | G15: SC-1020 | H15: SC-1020 | I15: SC-1020 | J15: SC-1020 | K15: SC-1020 | L15: SC-1020 | M15: SC-1020 | N15: SC-1020 | O15: SC-1020 | P15: SC-1020 | Q15: SC-1020 | R15: SC-1020 | S15: SC-1020 | T15: SC-1020 | U15: SC-1020 | V15: SC-1020 | W15: SC-1020 | X15: SC-1020 | Y15: SC-1020 | Z15: SC-1020 | AA15: SC-1020 | AB15: SC-1020 | AC15: SC-1020 | AD15: SC-1020 | AE15: SC-1020 | AF15: 1019 | AH15: =AG15+AF15-B15 -> 375 | AI15: 1386 | AK15: =AJ15+AI15-AF15 -> 367 | AO15: 202 | AP15: 1561 | AQ15: =AP15+AO15-AI15 -> 377 | AR15: 582 | AT15: =AS15+AR15-AO15 -> 380 | AU15: 961 | AW15: =AV15+AU15-AR15 -> 379 | AX15: 290 | AY15: 975 | AZ15: =AY15+AX15-AU15 -> 304 | BA15: 680 | BC15: =BB15+BA15-AX15 -> 390 | BD15: 1058 | BF15: =BE15+BD15-BA15 -> 378 | BJ15: 1157 | BL15: =BK15+BJ15-BD15 -> 99 | BM15: 1157 | BO15: =BN15+BM15-BJ15 -> 0 | BP15: 0 | BQ15: 1157 | BR15: =BQ15+BP15-BM15 -> 0 | BS15: 0 | BU15: =BT15+BS15-BP15 -> 0 | BV15: 0 | BX15: =BW15+BV15-BS15 -> 0 | BY15: 0 | CA15: =BZ15+BY15-BV15 -> 0 | CE15: 0 | CG15: =CF15+CE15-BY15 -> 0 | CH15: 229 | CJ15: =CI15+CH15-CE15 -> 229 | CK15: 574 | CM15: =CL15+CK15-CH15 -> 345 | CN15: 932 | CP15: =CO15+CN15-CK15 -> 358 | CQ15: 1289 | CS15: =CR15+CQ15-CN15 -> 357 | CT15: 57 | CU15: 1560 | CV15: =CU15+CT15-CQ15 -> 328 | CZ15: 414 | DB15: =DA15+CZ15-CT15 -> 357 | DC15: 768 | DE15: =DD15+DC15-CZ15 -> 354 | DF15: 357 | DG15: 772 | DH15: =DG15+DF15-DC15 -> 361 | DI15: 709 | DK15: =DJ15+DI15-DF15 -> 352 | DL15: 1070 | DN15: =DM15+DL15-DI15 -> 361 | DO15: 1400 | DQ15: =DP15+DO15-DL15 -> 330
A16: 12 | B16: 643 | D16: 373 | E16: SC-1020 | F16: SC-1020 | G16: SC-1020 | H16: SC-1020 | I16: SC-1020 | J16: SC-1020 | K16: SC-1020 | L16: SC-1020 | M16: SC-1020 | N16: SC-1020 | O16: SC-1020 | P16: SC-1020 | Q16: SC-1020 | R16: SC-1020 | S16: SC-1020 | T16: SC-1020 | U16: SC-1020 | V16: SC-1020 | W16: SC-1020 | X16: SC-1020 | Y16: SC-1020 | Z16: SC-1020 | AA16: SC-1020 | AB16: SC-1020 | AC16: SC-1020 | AD16: SC-1020 | AE16: SC-1020 | AF16: 1022 | AH16: =AG16+AF16-B16 -> 379 | AI16: 1361 | AK16: =AJ16+AI16-AF16 -> 339 | AO16: 187 | AP16: 1561 | AQ16: =AP16+AO16-AI16 -> 387 | AR16: 578 | AT16: =AS16+AR16-AO16 -> 391 | AU16: 953 | AW16: =AV16+AU16-AR16 -> 375 | AX16: 273 | AY16: 960 | AZ16: =AY16+AX16-AU16 -> 280 | BA16: 665 | BC16: =BB16+BA16-AX16 -> 392 | BD16: 1032 | BF16: =BE16+BD16-BA16 -> 367 | BJ16: 1130 | BL16: =BK16+BJ16-BD16 -> 98 | BM16: 1130 | BO16: =BN16+BM16-BJ16 -> 0 | BP16: 0 | BQ16: 1130 | BR16: =BQ16+BP16-BM16 -> 0 | BS16: 0 | BU16: =BT16+BS16-BP16 -> 0 | BV16: 0 | BX16: =BW16+BV16-BS16 -> 0 | BY16: 0 | CA16: =BZ16+BY16-BV16 -> 0 | CE16: 0 | CG16: =CF16+CE16-BY16 -> 0 | CH16: 282 | CJ16: =CI16+CH16-CE16 -> 282 | CK16: 643 | CM16: =CL16+CK16-CH16 -> 361 | CN16: 1013 | CP16: =CO16+CN16-CK16 -> 370 | CQ16: 336 | CR16: 1035 | CS16: =CR16+CQ16-CN16 -> 358 | CT16: 217 | CU16: 431 | CV16: =CU16+CT16-CQ16 -> 312 | CZ16: 593 | DB16: =DA16+CZ16-CT16 -> 376 | DC16: 963 | DE16: =DD16+DC16-CZ16 -> 370 | DF16: 1334 | DH16: =DG16+DF16-DC16 -> 371 | DI16: 129 | DJ16: 1560 | DK16: =DJ16+DI16-DF16 -> 355 | DL16: 499 | DN16: =DM16+DL16-DI16 -> 370 | DO16: 838 | DQ16: =DP16+DO16-DL16 -> 339
A17: 13 | B17: 289 | C17: 1412 | D17: 317 | E17: DR1073Z,DR856Z | F17: DR1073Z,DR856Z | G17: DR1073Z,DR856Z | H17: DR1073Z,DR856Z | I17: DR1073Z,DR856Z | J17: DR1073Z,DR856Z | K17: SC-1020 | L17: SC-1020 | M17: SC-1020 | N17: SC-1020 | O17: SC-1020 | P17: SC-1020 | Q17: SC-1020 | R17: SC-1020 | S17: SC-1020 | T17: SC-1020 | U17: SC-1020 | V17: SC-1020 | W17: SC-1020 | X17: SC-1020 | Y17: SC-1020 | Z17: SC-1020 | AA17: SC-1020 | AB17: SC-1020 | AC17: SC-1020 | AD17: SC-1020 | AE17: SC-1020 | AF17: 634 | AH17: =AG17+AF17-B17 -> 345 | AI17: 970 | AK17: =AJ17+AI17-AF17 -> 336 | AO17: 120 | AP17: 1200 | AQ17: =AP17+AO17-AI17 -> 350 | AR17: 470 | AT17: =AS17+AR17-AO17 -> 350 | AU17: 815 | AW17: =AV17+AU17-AR17 -> 345 | AX17: 281 | AY17: 824 | AZ17: =AY17+AX17-AU17 -> 290 | BA17: 666 | BC17: =BB17+BA17-AX17 -> 385 | BD17: 1031 | BF17: =BE17+BD17-BA17 -> 365 | BJ17: 1127 | BL17: =BK17+BJ17-BD17 -> 96 | BM17: 1127 | BO17: =BN17+BM17-BJ17 -> 0 | BP17: 0 | BQ17: 1127 | BR17: =BQ17+BP17-BM17 -> 0 | BS17: 0 | BU17: =BT17+BS17-BP17 -> 0 | BV17: 299 | BX17: =BW17+BV17-BS17 -> 299 | BY17: 661 | CA17: =BZ17+BY17-BV17 -> 362 | CE17: 1039 | CG17: =CF17+CE17-BY17 -> 378 | CH17: 1424 | CJ17: =CI17+CH17-CE17 -> 385 | CK17: 236 | CL17: 1570 | CM17: =CL17+CK17-CH17 -> 382 | CN17: 622 | CP17: =CO17+CN17-CK17 -> 386 | CQ17: 1004 | CS17: =CR17+CQ17-CN17 -> 382 | CT17: 1370 | CV17: =CU17+CT17-CQ17 -> 366 | CZ17: 240 | DA17: 1497 | DB17: =DA17+CZ17-CT17 -> 367 | DC17: 613 | DE17: =DD17+DC17-CZ17 -> 373 | DF17: 983 | DH17: =DG17+DF17-DC17 -> 370 | DI17: 329 | DJ17: 1013 | DK17: =DJ17+DI17-DF17 -> 359 | DL17: 698 | DN17: =DM17+DL17-DI17 -> 369 | DO17: 1039 | DQ17: =DP17+DO17-DL17 -> 341
A18: 14 | B18: 0 | C18: 1238 | D18: 161 | E18: 011-3 | F18: 011-3 | G18: 011-3 | H18: 011-3 | I18: 011-3 | J18: 011-3 | K18: 011-3 | L18: 011-3 | M18: 011-3 | N18: 011-3 | O18: 011-3 | P18: 011-3 | Q18: 011-3 | R18: 011-3 | S18: 011-3 | T18: 011-3 | U18: 011-3 | V18: 011-3 | W18: 011-3 | X18: 011-3 | Y18: 011-3 | Z18: 011-3 | AA18: SC-1020 | AB18: SC-1020 | AC18: SC-1020 | AD18: SC-1020 | AE18: SC-1020 | AF18: 356 | AH18: =AG18+AF18-B18 -> 356 | AI18: 720 | AK18: =AJ18+AI18-AF18 -> 364 | AO18: 1101 | AQ18: =AP18+AO18-AI18 -> 381 | AR18: 1482 | AT18: =AS18+AR18-AO18 -> 381 | AU18: 296 | AV18: 1560 | AW18: =AV18+AU18-AR18 -> 374 | AX18: 687 | AZ18: =AY18+AX18-AU18 -> 391 | BA18: 1078 | BC18: =BB18+BA18-AX18 -> 391 | BD18: 1453 | BF18: =BE18+BD18-BA18 -> 375 | BJ18: 281 | BK18: 1560 | BL18: =BK18+BJ18-BD18 -> 388 | BM18: 649 | BO18: =BN18+BM18-BJ18 -> 368 | BP18: 1028 | BR18: =BQ18+BP18-BM18 -> 379 | BS18: 1402 | BU18: =BT18+BS18-BP18 -> 374 | BV18: 233 | BW18: 1520 | BX18: =BW18+BV18-BS18 -> 351 | BY18: 588 | CA18: =BZ18+BY18-BV18 -> 355 | CE18: 967 | CG18: =CF18+CE18-BY18 -> 379 | CH18: 1339 | CJ18: =CI18+CH18-CE18 -> 372 | CK18: 145 | CL18: 1560 | CM18: =CL18+CK18-CH18 -> 366 | CN18: 522 | CP18: =CO18+CN18-CK18 -> 377 | CQ18: 890 | CS18: =CR18+CQ18-CN18 -> 368 | CT18: 1249 | CV18: =CU18+CT18-CQ18 -> 359 | CZ18: 1623 | DB18: =DA18+CZ18-CT18 -> 374 | DC18: 317 | DD18: 1629 | DE18: =DD18+DC18-CZ18 -> 323 | DF18: 694 | DH18: =DG18+DF18-DC18 -> 377 | DI18: 1069 | DK18: =DJ18+DI18-DF18 -> 375 | DL18: 1443 | DN18: =DM18+DL18-DI18 -> 374 | DO18: 221 | DP18: 1560 | DQ18: =DP18+DO18-DL18 -> 338
A19: 15 | B19: 9 | C19: 1560 | D19: 402 | E19: 011-3 61" | F19: 011-3 61" | G19: 011-3 | H19: 011-3 | I19: 011-3 | J19: 011-3 | K19: SC-1020 | L19: SC-1020 | M19: SC-1020 | N19: SC-1020 | O19: SC-1020 | P19: SC-1020 | Q19: SC-1020 | R19: SC-1020 | S19: SC-1020 | T19: SC-1020 | U19: SC-1020 | V19: SC-1020 | W19: SC-1020 | X19: SC-1020 | Y19: SC-1020 | Z19: SC-1020 | AA19: SC-1020 | AB19: SC-1020 | AC19: SC-1020 | AD19: SC-1020 | AE19: SC-1020 | AF19: 425 | AH19: =AG19+AF19-B19 -> 416 | AI19: 254 | AJ19: 480 | AK19: =AJ19+AI19-AF19 -> 309 | AO19: 631 | AQ19: =AP19+AO19-AI19 -> 377 | AR19: 1008 | AT19: =AS19+AR19-AO19 -> 377 | AU19: 1381 | AW19: =AV19+AU19-AR19 -> 373 | AX19: 275 | AY19: 1392 | AZ19: =AY19+AX19-AU19 -> 286 | BA19: 663 | BC19: =BB19+BA19-AX19 -> 388 | BD19: 1022 | BF19: =BE19+BD19-BA19 -> 359 | BJ19: 1120 | BL19: =BK19+BJ19-BD19 -> 98 | BM19: 1120 | BO19: =BN19+BM19-BJ19 -> 0 | BP19: 0 | BQ19: 1120 | BR19: =BQ19+BP19-BM19 -> 0 | BS19: 0 | BU19: =BT19+BS19-BP19 -> 0 | BV19: 303 | BX19: =BW19+BV19-BS19 -> 303 | BY19: 8 | BZ19: 655 | CA19: =BZ19+BY19-BV19 -> 360 | CE19: 394 | CG19: =CF19+CE19-BY19 -> 386 | CH19: 780 | CJ19: =CI19+CH19-CE19 -> 386 | CK19: 1157 | CM19: =CL19+CK19-CH19 -> 377 | CN19: 1540 | CP19: =CO19+CN19-CK19 -> 383 | CQ19: 350 | CR19: 1560 | CS19: =CR19+CQ19-CN19 -> 370 | CT19: 702 | CV19: =CU19+CT19-CQ19 -> 352 | CZ19: 1073 | DB19: =DA19+CZ19-CT19 -> 371 | DC19: 1436 | DE19: =DD19+DC19-CZ19 -> 363 | DF19: 230 | DG19: 1560 | DH19: =DG19+DF19-DC19 -> 354 | DI19: 582 | DK19: =DJ19+DI19-DF19 -> 352 | DL19: 934 | DN19: =DM19+DL19-DI19 -> 352 | DO19: 1266 | DQ19: =DP19+DO19-DL19 -> 332
A20: 16 | B20: 287 | C20: 1560 | D20: 369 | E20: 011-3 | F20: 011-3 | G20: 011-3 | H20: 011-3 | I20: 011-3 | J20: 011-3 | K20: 011-3 | L20: 011-3 | M20: 011-3 | N20: 011-3 | O20: 011-3 | P20: 011-3 | Q20: 011-3 | R20: 011-3 | S20: 011-3 | T20: 011-3 | U20: 011-3 | V20: 011-3 | W20: 011-4 | X20: 011-4 | Y20: 011-4 | Z20: 011-4 | AA20: 011-4 | AB20: 011-4 | AC20: 011-4 | AD20: 011-4 | AE20: 011-4 | AF20: 669 | AH20: =AG20+AF20-B20 -> 382 | AI20: 1024 | AK20: =AJ20+AI20-AF20 -> 355 | AO20: 1408 | AQ20: =AP20+AO20-AI20 -> 384 | AR20: 230 | AS20: 1560 | AT20: =AS20+AR20-AO20 -> 382 | AU20: 609 | AW20: =AV20+AU20-AR20 -> 379 | AX20: 990 | AZ20: =AY20+AX20-AU20 -> 381 | BA20: 1371 | BC20: =BB20+BA20-AX20 -> 381 | BD20: 177 | BE20: 1560 | BF20: =BE20+BD20-BA20 -> 366 | BJ20: 536 | BL20: =BK20+BJ20-BD20 -> 359 | BM20: 916 | BO20: =BN20+BM20-BJ20 -> 380 | BP20: 1300 | BR20: =BQ20+BP20-BM20 -> 384 | BS20: 123 | BT20: 1560 | BU20: =BT20+BS20-BP20 -> 383 | BV20: 505 | BX20: =BW20+BV20-BS20 -> 382 | BY20: 863 | CA20: =BZ20+BY20-BV20 -> 358 | CE20: 1229 | CG20: =CF20+CE20-BY20 -> 366 | CH20: 39 | CI20: 1560 | CJ20: =CI20+CH20-CE20 -> 370 | CK20: 0 | CL20: 359 | CM20: =CL20+CK20-CH20 -> 320 | CN20: 340 | CP20: =CO20+CN20-CK20 -> 340 | CQ20: 712 | CS20: =CR20+CQ20-CN20 -> 372 | CT20: 1065 | CV20: =CU20+CT20-CQ20 -> 353 | CZ20: 1425 | DB20: =DA20+CZ20-CT20 -> 360 | DC20: 237 | DD20: 1560 | DE20: =DD20+DC20-CZ20 -> 372 | DF20: 613 | DH20: =DG20+DF20-DC20 -> 376 | DI20: 992 | DK20: =DJ20+DI20-DF20 -> 379 | DL20: 1371 | DN20: =DM20+DL20-DI20 -> 379 | DO20: 158 | DP20: 1560 | DQ20: =DP20+DO20-DL20 -> 347
A21: 17 | B21: 575 | D21: 330 | E21: DR1073Z,DR856Z | F21: DR1073Z,DR856Z | G21: DR1073Z,DR856Z | H21: DR1073Z,DR856Z | I21: DR1073Z,DR856Z | J21: DR1073Z,DR856Z | K21: DR1073Z,DR856Z | L21: DR1073Z,DR856Z | M21: DR1073Z,DR856Z | N21: 011-3 | O21: 011-3 | P21: 011-3 | Q21: 011-3 | R21: 011-3 | S21: 011-3 | T21: 011-3 | U21: 011-3 | V21: 011-3 | W21: 011-3 | X21: 011-3 | Y21: 011-3 | Z21: 011-3 | AA21: 011-3 | AB21: 011-3 | AC21: 011-3 | AD21: 011-3 | AE21: 011-3 | AF21: 917 | AH21: =AG21+AF21-B21 -> 342 | AI21: 208 | AJ21: 1024 | AK21: =AJ21+AI21-AF21 -> 315 | AO21: 549 | AQ21: =AP21+AO21-AI21 -> 341 | AR21: 901 | AT21: =AS21+AR21-AO21 -> 352 | AU21: 43 | AV21: 1200 | AW21: =AV21+AU21-AR21 -> 342 | AX21: 388 | AZ21: =AY21+AX21-AU21 -> 345 | BA21: 734 | BC21: =BB21+BA21-AX21 -> 346 | BD21: 0 | BE21: 980 | BF21: =BE21+BD21-BA21 -> 246 | BJ21: 273 | BL21: =BK21+BJ21-BD21 -> 273 | BM21: 623 | BO21: =BN21+BM21-BJ21 -> 350 | BP21: 987 | BR21: =BQ21+BP21-BM21 -> 364 | BS21: 1349 | BU21: =BT21+BS21-BP21 -> 362 | BV21: 156 | BW21: 1560 | BX21: =BW21+BV21-BS21 -> 367 | BY21: 508 | CA21: =BZ21+BY21-BV21 -> 352 | CE21: 876 | CG21: =CF21+CE21-BY21 -> 368 | CH21: 1241 | CJ21: =CI21+CH21-CE21 -> 365 | CK21: 32 | CL21: 1560 | CM21: =CL21+CK21-CH21 -> 351 | CN21: 404 | CP21: =CO21+CN21-CK21 -> 372 | CQ21: 781 | CS21: =CR21+CQ21-CN21 -> 377 | CT21: 1123 | CV21: =CU21+CT21-CQ21 -> 342 | CZ21: 1497 | DB21: =DA21+CZ21-CT21 -> 374 | DC21: 292 | DD21: 1570 | DE21: =DD21+DC21-CZ21 -> 365 | DF21: 666 | DH21: =DG21+DF21-DC21 -> 374 | DI21: 1034 | DK21: =DJ21+DI21-DF21 -> 368 | DL21: 1402 | DN21: =DM21+DL21-DI21 -> 368 | DO21: 245 | DP21: 1495 | DQ21: =DP21+DO21-DL21 -> 338
A22: 18 | B22: 810 | D22: 330 | E22: DR1073Z,DR856Z | F22: DR1073Z,DR856Z | G22: DR1073Z,DR856Z | H22: DR1073Z,DR856Z | I22: DR1073Z,DR856Z | J22: DR1073Z,DR856Z | K22: DR1073Z,DR856Z | L22: DR1073Z,DR856Z | M22: DR1073Z,DR856Z | N22: SC-1020 | O22: SC-1020 | P22: SC-1020 | Q22: SC-1020 | R22: SC-1020 | S22: SC-1020 | T22: SC-1020 | U22: SC-1020 | V22: SC-1020 | W22: SC-1020 | X22: SC-1020 | Y22: SC-1020 | Z22: SC-1020 | AA22: SC-1020 | AB22: SC-1020 | AC22: SC-1020 | AD22: 011-4 | AE22: 011-4 | AF22: 1158 | AH22: =AG22+AF22-B22 -> 348 | AI22: 291 | AJ22: 1200 | AK22: =AJ22+AI22-AF22 -> 333 | AO22: 642 | AQ22: =AP22+AO22-AI22 -> 351 | AR22: 990 | AT22: =AS22+AR22-AO22 -> 348 | AU22: 136 | AV22: 1200 | AW22: =AV22+AU22-AR22 -> 346 | AX22: 485 | AZ22: =AY22+AX22-AU22 -> 349 | BA22: 835 | BC22: =BB22+BA22-AX22 -> 350 | BD22: 0 | BE22: 1200 | BF22: =BE22+BD22-BA22 -> 365 | BJ22: 0 | BL22: =BK22+BJ22-BD22 -> 0 | BM22: 0 | BO22: =BN22+BM22-BJ22 -> 0 | BP22: 0 | BR22: =BQ22+BP22-BM22 -> 0 | BS22: 0 | BU22: =BT22+BS22-BP22 -> 0 | BV22: 173 | BW22: 170 | BX22: =BW22+BV22-BS22 -> 343 | BY22: 524 | CA22: =BZ22+BY22-BV22 -> 351 | CE22: 893 | CG22: =CF22+CE22-BY22 -> 369 | CH22: 1270 | CJ22: =CI22+CH22-CE22 -> 377 | CK22: 1482 | CM22: =CL22+CK22-CH22 -> 212 | CN22: 296 | CO22: 1560 | CP22: =CO22+CN22-CK22 -> 374 | CQ22: 671 | CS22: =CR22+CQ22-CN22 -> 375 | CT22: 1025 | CV22: =CU22+CT22-CQ22 -> 354 | CZ22: 1403 | DB22: =DA22+CZ22-CT22 -> 378 | DC22: 216 | DD22: 1560 | DE22: =DD22+DC22-CZ22 -> 373 | DF22: 591 | DH22: =DG22+DF22-DC22 -> 375 | DI22: 0 | DJ22: 792 | DK22: =DJ22+DI22-DF22 -> 201 | DL22: 349 | DN22: =DM22+DL22-DI22 -> 349 | DO22: 695 | DQ22: =DP22+DO22-DL22 -> 346
A23: 19 | B23: 982 | D23: 374 | E23: 011-3 | F23: 011-3 | G23: 011-3 | H23: 011-3 | I23: 011-3 | J23: 011-3 | K23: 011-3 | L23: 011-3 | M23: 011-3 | N23: 011-3 | O23: 011-3 | P23: 011-3 | Q23: 011-3 | R23: 011-3 | S23: 011-3 | T23: 011-3 | U23: SC-1020 | V23: SC-1020 | W23: SC-1020 | X23: SC-1020 | Y23: SC-1020 | Z23: SC-1020 | AA23: SC-1020 | AB23: SC-1020 | AC23: SC-1020 | AD23: SC-1020 | AE23: SC-1020 | AF23: 1352 | AH23: =AG23+AF23-B23 -> 370 | AI23: 175 | AJ23: 1535 | AK23: =AJ23+AI23-AF23 -> 358 | AO23: 555 | AQ23: =AP23+AO23-AI23 -> 380 | AR23: 933 | AT23: =AS23+AR23-AO23 -> 378 | AU23: 1309 | AW23: =AV23+AU23-AR23 -> 376 | AX23: 119 | AY23: 1560 | AZ23: =AY23+AX23-AU23 -> 370 | BA23: 477 | BC23: =BB23+BA23-AX23 -> 358 | BD23: 830 | BF23: =BE23+BD23-BA23 -> 353 | BJ23: 1195 | BL23: =BK23+BJ23-BD23 -> 365 | BM23: 1558 | BO23: =BN23+BM23-BJ23 -> 363 | BP23: 364 | BQ23: 1560 | BR23: =BQ23+BP23-BM23 -> 366 | BS23: 730 | BU23: =BT23+BS23-BP23 -> 366 | BV23: 1097 | BX23: =BW23+BV23-BS23 -> 367 | BY23: 119 | BZ23: 1275 | CA23: =BZ23+BY23-BV23 -> 297 | CE23: 0 | CF23: 391 | CG23: =CF23+CE23-BY23 -> 272 | CH23: 272 | CJ23: =CI23+CH23-CE23 -> 272 | CK23: 631 | CM23: =CL23+CK23-CH23 -> 359 | CN23: 998 | CP23: =CO23+CN23-CK23 -> 367 | CQ23: 1364 | CS23: =CR23+CQ23-CN23 -> 366 | CT23: 152 | CU23: 1560 | CV23: =CU23+CT23-CQ23 -> 348 | CZ23: 522 | DB23: =DA23+CZ23-CT23 -> 370 | DC23: 888 | DE23: =DD23+DC23-CZ23 -> 366 | DF23: 1253 | DH23: =DG23+DF23-DC23 -> 365 | DI23: 44 | DJ23: 1570 | DK23: =DJ23+DI23-DF23 -> 361 | DL23: 412 | DN23: =DM23+DL23-DI23 -> 368 | DO23: 751 | DQ23: =DP23+DO23-DL23 -> 339
A24: 20 | B24: 694 | D24: 333 | E24: ABZ85,DR794Z,DR856Z | F24: ABZ85,DR794Z,DR856Z | G24: ABZ85,DR794Z,DR856Z | H24: DR1073Z,DR856Z | I24: DR1073Z,DR856Z | J24: DR1073Z,DR856Z | K24: SC-1020 | L24: SC-1020 | M24: SC-1020 | N24: SC-1020 | O24: SC-1020 | P24: SC-1020 | Q24: SC-1020 | R24: SC-1020 | S24: SC-1020 | T24: SC-1020 | U24: SC-1020 | V24: SC-1020 | W24: SC-1020 | X24: SC-1020 | Y24: SC-1020 | Z24: SC-1020 | AA24: SC-1020 | AB24: SC-1020 | AC24: SC-1020 | AD24: SC-1020 | AE24: SC-1020 | AF24: 1037 | AH24: =AG24+AF24-B24 -> 343 | AI24: 0 | AJ24: 1285 | AK24: =AJ24+AI24-AF24 -> 248 | AO24: 335 | AQ24: =AP24+AO24-AI24 -> 335 | AR24: 685 | AT24: =AS24+AR24-AO24 -> 350 | AU24: 1032 | AW24: =AV24+AU24-AR24 -> 347 | AX24: 277 | AY24: 1049 | AZ24: =AY24+AX24-AU24 -> 294 | BA24: 656 | BC24: =BB24+BA24-AX24 -> 379 | BD24: 1023 | BF24: =BE24+BD24-BA24 -> 367 | BJ24: 1 | BK24: 1400 | BL24: =BK24+BJ24-BD24 -> 378 | BM24: 362 | BO24: =BN24+BM24-BJ24 -> 361 | BP24: 731 | BR24: =BQ24+BP24-BM24 -> 369 | BS24: 1098 | BU24: =BT24+BS24-BP24 -> 367 | BV24: 1466 | BX24: =BW24+BV24-BS24 -> 368 | BY24: 241 | BZ24: 1560 | CA24: =BZ24+BY24-BV24 -> 335 | CE24: 84 | CF24: 512 | CG24: =CF24+CE24-BY24 -> 355 | CH24: 458 | CJ24: =CI24+CH24-CE24 -> 374 | CK24: 824 | CM24: =CL24+CK24-CH24 -> 366 | CN24: 1190 | CP24: =CO24+CN24-CK24 -> 366 | CQ24: 1551 | CS24: =CR24+CQ24-CN24 -> 361 | CT24: 331 | CU24: 1560 | CV24: =CU24+CT24-CQ24 -> 340 | CZ24: 681 | DB24: =DA24+CZ24-CT24 -> 350 | DC24: 1043 | DE24: =DD24+DC24-CZ24 -> 362 | DF24: 1397 | DH24: =DG24+DF24-DC24 -> 354 | DI24: 194 | DJ24: 1560 | DK24: =DJ24+DI24-DF24 -> 357 | DL24: 552 | DN24: =DM24+DL24-DI24 -> 358 | DO24: 876 | DQ24: =DP24+DO24-DL24 -> 324
A25: 21 | B25: 612 | D25: 361 | E25: SC-1020 | F25: SC-1020 | G25: SC-1020 | H25: SC-1020 | I25: SC-1020 | J25: SC-1020 | K25: SC-1020 | L25: SC-1020 | M25: SC-1020 | N25: SC-1020 | O25: SC-1020 | P25: SC-1020 | Q25: SC-1020 | R25: SC-1020 | S25: SC-1020 | T25: SC-1020 | U25: SC-1020 | V25: SC-1020 | W25: SC-1020 | X25: SC-1020 | Y25: SC-1020 | Z25: SC-1020 | AA25: SC-1020 | AB25: SC-1020 | AC25: SC-1020 | AD25: SC-1020 | AE25: SC-1020 | AF25: 987 | AH25: =AG25+AF25-B25 -> 375 | AI25: 1340 | AK25: =AJ25+AI25-AF25 -> 353 | AO25: 231 | AP25: 1459 | AQ25: =AP25+AO25-AI25 -> 350 | AR25: 602 | AT25: =AS25+AR25-AO25 -> 371 | AU25: 950 | AW25: =AV25+AU25-AR25 -> 348 | AX25: 1317 | AZ25: =AY25+AX25-AU25 -> 367 | BA25: 115 | BB25: 1560 | BC25: =BB25+BA25-AX25 -> 358 | BD25: 460 | BF25: =BE25+BD25-BA25 -> 345 | BJ25: 328 | BK25: 496 | BL25: =BK25+BJ25-BD25 -> 364 | BM25: 691 | BO25: =BN25+BM25-BJ25 -> 363 | BP25: 1060 | BR25: =BQ25+BP25-BM25 -> 369 | BS25: 1423 | BU25: =BT25+BS25-BP25 -> 363 | BV25: 231 | BW25: 1560 | BX25: =BW25+BV25-BS25 -> 368 | BY25: 579 | CA25: =BZ25+BY25-BV25 -> 348 | CE25: 327 | CF25: 615 | CG25: =CF25+CE25-BY25 -> 363 | CH25: 0 | CI25: 606 | CJ25: =CI25+CH25-CE25 -> 279 | CK25: 332 | CM25: =CL25+CK25-CH25 -> 332 | CN25: 696 | CP25: =CO25+CN25-CK25 -> 364 | CQ25: 1057 | CS25: =CR25+CQ25-CN25 -> 361 | CT25: 1391 | CV25: =CU25+CT25-CQ25 -> 334 | CZ25: 201 | DA25: 1560 | DB25: =DA25+CZ25-CT25 -> 370 | DC25: 567 | DE25: =DD25+DC25-CZ25 -> 366 | DF25: 934 | DH25: =DG25+DF25-DC25 -> 367 | DI25: 1291 | DK25: =DJ25+DI25-DF25 -> 357 | DL25: 100 | DM25: 1560 | DN25: =DM25+DL25-DI25 -> 369 | DO25: 439 | DQ25: =DP25+DO25-DL25 -> 339
A26: 22 | B26: 57 | C26: 1561 | D26: 368 | E26: 011-3 | F26: 011-3 | G26: 011-3 | H26: 011-3 | I26: 011-3 | J26: 011-3 | K26: 011-3 | L26: 011-3 | M26: 011-3 | N26: 011-3 | O26: 011-3 | P26: 011-3 | Q26: 011-3 | R26: 011-3 | S26: SC-1020 | T26: SC-1020 | U26: SC-1020 | V26: SC-1020 | W26: SC-1020 | X26: SC-1020 | Y26: SC-1020 | Z26: SC-1020 | AA26: SC-1020 | AB26: SC-1020 | AC26: SC-1020 | AD26: SC-1020 | AE26: SC-1020 | AF26: 438 | AH26: =AG26+AF26-B26 -> 381 | AI26: 801 | AK26: =AJ26+AI26-AF26 -> 363 | AO26: 1181 | AQ26: =AP26+AO26-AI26 -> 380 | AR26: 1 | AS26: 1560 | AT26: =AS26+AR26-AO26 -> 380 | AU26: 365 | AW26: =AV26+AU26-AR26 -> 364 | AX26: 738 | AZ26: =AY26+AX26-AU26 -> 373 | BA26: 1111 | BC26: =BB26+BA26-AX26 -> 373 | BD26: 1476 | BF26: =BE26+BD26-BA26 -> 365 | BJ26: 290 | BK26: 1560 | BL26: =BK26+BJ26-BD26 -> 374 | BM26: 627 | BO26: =BN26+BM26-BJ26 -> 337 | BP26: 1021 | BR26: =BQ26+BP26-BM26 -> 394 | BS26: 0 | BT26: 1384 | BU26: =BT26+BS26-BP26 -> 363 | BV26: 0 | BX26: =BW26+BV26-BS26 -> 0 | BY26: 0 | CA26: =BZ26+BY26-BV26 -> 0 | CE26: 0 | CG26: =CF26+CE26-BY26 -> 0 | CH26: 276 | CJ26: =CI26+CH26-CE26 -> 276 | CK26: 628 | CM26: =CL26+CK26-CH26 -> 352 | CN26: 984 | CP26: =CO26+CN26-CK26 -> 356 | CQ26: 1343 | CS26: =CR26+CQ26-CN26 -> 359 | CT26: 137 | CU26: 1560 | CV26: =CU26+CT26-CQ26 -> 354 | CZ26: 511 | DB26: =DA26+CZ26-CT26 -> 374 | DC26: 882 | DE26: =DD26+DC26-CZ26 -> 371 | DF26: 1254 | DH26: =DG26+DF26-DC26 -> 372 | DI26: 64 | DJ26: 1557 | DK26: =DJ26+DI26-DF26 -> 367 | DL26: 435 | DN26: =DM26+DL26-DI26 -> 371 | DO26: 773 | DQ26: =DP26+DO26-DL26 -> 338
A27: 23 | B27: 0 | C27: 595 | D27: 263 | E27: SC-1020 | F27: SC-1020 | G27: SC-1020 | H27: SC-1020 | I27: SC-1020 | J27: SC-1020 | K27: SC-1020 | L27: SC-1020 | M27: SC-1020 | N27: SC-1020 | O27: SC-1020 | P27: SC-1020 | Q27: SC-1020 | R27: SC-1020 | S27: SC-1020 | T27: SC-1020 | U27: SC-1020 | V27: SC-1020 | W27: SC-1020 | X27: SC-1020 | Y27: SC-1020 | Z27: SC-1020 | AA27: SC-1020 | AB27: SC-1020 | AC27: SC-1020 | AD27: SC-1020 | AE27: SC-1020 | AF27: 346 | AH27: =AG27+AF27-B27 -> 346 | AI27: 709 | AK27: =AJ27+AI27-AF27 -> 363 | AO27: 1089 | AQ27: =AP27+AO27-AI27 -> 380 | AR27: 1470 | AT27: =AS27+AR27-AO27 -> 381 | AU27: 284 | AV27: 1560 | AW27: =AV27+AU27-AR27 -> 374 | AX27: 665 | AZ27: =AY27+AX27-AU27 -> 381 | BA27: 1044 | BC27: =BB27+BA27-AX27 -> 379 | BD27: 1412 | BF27: =BE27+BD27-BA27 -> 368 | BJ27: 227 | BK27: 1560 | BL27: =BK27+BJ27-BD27 -> 375 | BM27: 598 | BO27: =BN27+BM27-BJ27 -> 371 | BP27: 976 | BR27: =BQ27+BP27-BM27 -> 378 | BS27: 1343 | BU27: =BT27+BS27-BP27 -> 367 | BV27: 155 | BW27: 1560 | BX27: =BW27+BV27-BS27 -> 372 | BY27: 515 | CA27: =BZ27+BY27-BV27 -> 360 | CE27: 886 | CG27: =CF27+CE27-BY27 -> 371 | CH27: 1262 | CJ27: =CI27+CH27-CE27 -> 376 | CK27: 1471 | CM27: =CL27+CK27-CH27 -> 209 | CN27: 285 | CO27: 1560 | CP27: =CO27+CN27-CK27 -> 374 | CQ27: 658 | CS27: =CR27+CQ27-CN27 -> 373 | CT27: 1009 | CV27: =CU27+CT27-CQ27 -> 351 | CZ27: 1385 | DB27: =DA27+CZ27-CT27 -> 376 | DC27: 0 | DD27: 1628 | DE27: =DD27+DC27-CZ27 -> 243 | DF27: 318 | DH27: =DG27+DF27-DC27 -> 318 | DI27: 691 | DK27: =DJ27+DI27-DF27 -> 373 | DL27: 1067 | DN27: =DM27+DL27-DI27 -> 376 | DO27: 1417 | DQ27: =DP27+DO27-DL27 -> 350
A28: 24 | B28: 0 | C28: 975 | D28: 210 | E28: SC-1020 | F28: SC-1020 | G28: SC-1020 | H28: SC-1020 | I28: SC-1020 | J28: SC-1020 | K28: SC-1020 | L28: SC-1020 | M28: SC-1020 | N28: SC-1020 | O28: SC-1020 | P28: SC-1020 | Q28: SC-1020 | R28: SC-1020 | S28: SC-1020 | T28: SC-1020 | U28: SC-1020 | V28: SC-1020 | W28: SC-1020 | X28: SC-1020 | Y28: SC-1020 | Z28: SC-1020 | AA28: SC-1020 | AB28: SC-1020 | AC28: SC-1020 | AD28: SC-1020 | AE28: SC-1020 | AF28: 349 | AH28: =AG28+AF28-B28 -> 349 | AI28: 709 | AK28: =AJ28+AI28-AF28 -> 360 | AO28: 1088 | AQ28: =AP28+AO28-AI28 -> 379 | AR28: 1463 | AT28: =AS28+AR28-AO28 -> 375 | AU28: 276 | AV28: 1560 | AW28: =AV28+AU28-AR28 -> 373 | AX28: 657 | AZ28: =AY28+AX28-AU28 -> 381 | BA28: 1035 | BC28: =BB28+BA28-AX28 -> 378 | BD28: 1394 | BF28: =BE28+BD28-BA28 -> 359 | BJ28: 214 | BK28: 1560 | BL28: =BK28+BJ28-BD28 -> 380 | BM28: 588 | BO28: =BN28+BM28-BJ28 -> 374 | BP28: 959 | BR28: =BQ28+BP28-BM28 -> 371 | BS28: 1329 | BU28: =BT28+BS28-BP28 -> 370 | BV28: 133 | BW28: 1560 | BX28: =BW28+BV28-BS28 -> 364 | BY28: 475 | CA28: =BZ28+BY28-BV28 -> 342 | CE28: 850 | CG28: =CF28+CE28-BY28 -> 375 | CH28: 1227 | CJ28: =CI28+CH28-CE28 -> 377 | CK28: 1435 | CM28: =CL28+CK28-CH28 -> 208 | CN28: 251 | CO28: 1560 | CP28: =CO28+CN28-CK28 -> 376 | CQ28: 618 | CS28: =CR28+CQ28-CN28 -> 367 | CT28: 958 | CV28: =CU28+CT28-CQ28 -> 340 | CZ28: 1329 | DB28: =DA28+CZ28-CT28 -> 371 | DC28: 0 | DD28: 1623 | DE28: =DD28+DC28-CZ28 -> 294 | DF28: 311 | DH28: =DG28+DF28-DC28 -> 311 | DI28: 680 | DK28: =DJ28+DI28-DF28 -> 369 | DL28: 1048 | DN28: =DM28+DL28-DI28 -> 368 | DO28: 1384 | DQ28: =DP28+DO28-DL28 -> 336
A29: 25 | B29: 728 | D29: 268 | E29: RD159Z | F29: RD159Z | G29: RD159Z | H29: RD159Z | I29: RD159Z | J29: RD159Z | K29: RD159Z | L29: RD159Z | M29: RD159Z | N29: RD159Z | O29: RD159Z | P29: RD159Z | Q29: SC-1020 | R29: SC-1020 | S29: SC-1020 | T29: SC-1020 | U29: SC-1020 | V29: SC-1020 | W29: SC-1020 | X29: SC-1020 | Y29: SC-1020 | Z29: SC-1020 | AA29: SC-1020 | AB29: SC-1020 | AC29: SC-1020 | AD29: SC-1020 | AE29: SC-1020 | AF29: 1000 | AH29: =AG29+AF29-B29 -> 272 | AI29: 1236 | AK29: =AJ29+AI29-AF29 -> 236 | AO29: 96 | AP29: 1425 | AQ29: =AP29+AO29-AI29 -> 285 | AR29: 383 | AT29: =AS29+AR29-AO29 -> 287 | AU29: 665 | AW29: =AV29+AU29-AR29 -> 282 | AX29: 950 | AZ29: =AY29+AX29-AU29 -> 285 | BA29: 1231 | BC29: =BB29+BA29-AX29 -> 281 | BD29: 6 | BE29: 1500 | BF29: =BE29+BD29-BA29 -> 275 | BJ29: 291 | BL29: =BK29+BJ29-BD29 -> 285 | BM29: 0 | BN29: 459 | BO29: =BN29+BM29-BJ29 -> 168 | BP29: 0 | BR29: =BQ29+BP29-BM29 -> 0 | BS29: 313 | BU29: =BT29+BS29-BP29 -> 313 | BV29: 669 | BX29: =BW29+BV29-BS29 -> 356 | BY29: 1005 | CA29: =BZ29+BY29-BV29 -> 336 | CE29: 280 | CF29: 1073 | CG29: =CF29+CE29-BY29 -> 348 | CH29: 554 | CJ29: =CI29+CH29-CE29 -> 274 | CK29: 0 | CL29: 751 | CM29: =CL29+CK29-CH29 -> 197 | CN29: 30 | CP29: =CO29+CN29-CK29 -> 30 | CQ29: 392 | CS29: =CR29+CQ29-CN29 -> 362 | CT29: 741 | CV29: =CU29+CT29-CQ29 -> 349 | CZ29: 1107 | DB29: =DA29+CZ29-CT29 -> 366 | DC29: 222 | DD29: 1224 | DE29: =DD29+DC29-CZ29 -> 339 | DF29: 556 | DH29: =DG29+DF29-DC29 -> 334 | DI29: 273 | DJ29: 628 | DK29: =DJ29+DI29-DF29 -> 345 | DL29: 632 | DN29: =DM29+DL29-DI29 -> 359 | DO29: 963 | DQ29: =DP29+DO29-DL29 -> 331
A30: 26 | B30: 587 | D30: 362 | E30: SC-1020 | F30: SC-1020 | G30: SC-1020 | H30: SC-1020 | I30: SC-1020 | J30: SC-1020 | K30: SC-1020 | L30: SC-1020 | M30: SC-1020 | N30: SC-1020 | O30: SC-1020 | P30: SC-1020 | Q30: SC-1020 | R30: SC-1020 | S30: SC-1020 | T30: SC-1020 | U30: SC-1020 | V30: 011-4 | W30: 011-4 | X30: 011-4 | Y30: 011-4 | Z30: 011-4 | AA30: 011-4 | AB30: 011-4 | AC30: 011-4 | AD30: 011-4 | AE30: 011-4 | AF30: 185 | AG30: 751 | AH30: =AG30+AF30-B30 -> 349 | AI30: 527 | AK30: =AJ30+AI30-AF30 -> 342 | AO30: 348 | AP30: 539 | AQ30: =AP30+AO30-AI30 -> 360 | AR30: 697 | AT30: =AS30+AR30-AO30 -> 349 | AU30: 1055 | AW30: =AV30+AU30-AR30 -> 358 | AX30: 1431 | AZ30: =AY30+AX30-AU30 -> 376 | BA30: 249 | BB30: 1560 | BC30: =BB30+BA30-AX30 -> 378 | BD30: 618 | BF30: =BE30+BD30-BA30 -> 369 | BJ30: 998 | BL30: =BK30+BJ30-BD30 -> 380 | BM30: 24 | BN30: 1318 | BO30: =BN30+BM30-BJ30 -> 344 | BP30: 65 | BQ30: 317 | BR30: =BQ30+BP30-BM30 -> 358 | BS30: 414 | BU30: =BT30+BS30-BP30 -> 349 | BV30: 297 | BW30: 462 | BX30: =BW30+BV30-BS30 -> 345 | BY30: 639 | CA30: =BZ30+BY30-BV30 -> 342 | CE30: 134 | CF30: 847 | CG30: =CF30+CE30-BY30 -> 342 | CH30: 424 | CJ30: =CI30+CH30-CE30 -> 290 | CK30: 275 | CL30: 492 | CM30: =CL30+CK30-CH30 -> 343 | CN30: 647 | CP30: =CO30+CN30-CK30 -> 372 | CQ30: 1023 | CS30: =CR30+CQ30-CN30 -> 376 | CT30: 1382 | CV30: =CU30+CT30-CQ30 -> 359 | CZ30: 223 | DA30: 1528 | DB30: =DA30+CZ30-CT30 -> 369 | DC30: 582 | DE30: =DD30+DC30-CZ30 -> 359 | DF30: 275 | DG30: 672 | DH30: =DG30+DF30-DC30 -> 365 | DI30: 641 | DK30: =DJ30+DI30-DF30 -> 366 | DL30: 255 | DM30: 753 | DN30: =DM30+DL30-DI30 -> 367 | DO30: 587 | DQ30: =DP30+DO30-DL30 -> 332
A31: 27 | B31: 314 | C31: 1560 | D31: 363 | E31: 011-3 | F31: 011-3 | G31: 011-3 | H31: 011-3 | I31: 011-3 | J31: 011-3 | K31: 011-3 | L31: 011-3 | M31: 011-3 | N31: 011-3 | O31: 011-3 | P31: 011-3 | Q31: 011-3 | R31: 011-3 | S31: 011-3 | T31: 011-3 | U31: 011-3 | V31: SC-1020 | W31: SC-1020 | X31: SC-1020 | Y31: SC-1020 | Z31: SC-1020 | AA31: SC-1020 | AB31: SC-1020 | AC31: SC-1020 | AD31: SC-1020 | AE31: SC-1020 | AF31: 690 | AH31: =AG31+AF31-B31 -> 376 | AI31: 1048 | AK31: =AJ31+AI31-AF31 -> 358 | AO31: 1426 | AQ31: =AP31+AO31-AI31 -> 378 | AR31: 234 | AS31: 1560 | AT31: =AS31+AR31-AO31 -> 368 | AU31: 604 | AW31: =AV31+AU31-AR31 -> 370 | AX31: 985 | AZ31: =AY31+AX31-AU31 -> 381 | BA31: 1361 | BC31: =BB31+BA31-AX31 -> 376 | BD31: 169 | BE31: 1560 | BF31: =BE31+BD31-BA31 -> 368 | BJ31: 551 | BL31: =BK31+BJ31-BD31 -> 382 | BM31: 925 | BO31: =BN31+BM31-BJ31 -> 374 | BP31: 1307 | BR31: =BQ31+BP31-BM31 -> 382 | BS31: 136 | BT31: 1540 | BU31: =BT31+BS31-BP31 -> 369 | BV31: 508 | BX31: =BW31+BV31-BS31 -> 372 | BY31: 862 | CA31: =BZ31+BY31-BV31 -> 354 | CE31: 1229 | CG31: =CF31+CE31-BY31 -> 367 | CH31: 1524 | CJ31: =CI31+CH31-CE31 -> 295 | CK31: 241 | CL31: 1638 | CM31: =CL31+CK31-CH31 -> 355 | CN31: 600 | CP31: =CO31+CN31-CK31 -> 359 | CQ31: 964 | CS31: =CR31+CQ31-CN31 -> 364 | CT31: 1306 | CV31: =CU31+CT31-CQ31 -> 342 | CZ31: 105 | DA31: 1560 | DB31: =DA31+CZ31-CT31 -> 359 | DC31: 464 | DE31: =DD31+DC31-CZ31 -> 359 | DF31: 832 | DH31: =DG31+DF31-DC31 -> 368 | DI31: 1199 | DK31: =DJ31+DI31-DF31 -> 367 | DL31: 7 | DM31: 1560 | DN31: =DM31+DL31-DI31 -> 368 | DO31: 344 | DQ31: =DP31+DO31-DL31 -> 337
A32: 28 | B32: 669 | D32: 375 | E32: SC-1020 | F32: SC-1020 | G32: SC-1020 | H32: SC-1020 | I32: SC-1020 | J32: SC-1020 | K32: SC-1020 | L32: SC-1020 | M32: SC-1020 | N32: SC-1020 | O32: SC-1020 | P32: SC-1020 | Q32: SC-1020 | R32: SC-1020 | S32: SC-1020 | T32: SC-1020 | U32: SC-1020 | V32: SC-1020 | W32: SC-1020 | X32: SC-1020 | Y32: SC-1020 | Z32: SC-1020 | AA32: SC-1020 | AB32: SC-1020 | AC32: SC-1020 | AD32: SC-1020 | AE32: SC-1020 | AF32: 1038 | AH32: =AG32+AF32-B32 -> 369 | AI32: 1394 | AK32: =AJ32+AI32-AF32 -> 356 | AO32: 202 | AP32: 1561 | AQ32: =AP32+AO32-AI32 -> 369 | AR32: 569 | AT32: =AS32+AR32-AO32 -> 367 | AU32: 934 | AW32: =AV32+AU32-AR32 -> 365 | AX32: 1316 | AZ32: =AY32+AX32-AU32 -> 382 | BA32: 136 | BB32: 1560 | BC32: =BB32+BA32-AX32 -> 380 | BD32: 506 | BF32: =BE32+BD32-BA32 -> 370 | BJ32: 890 | BL32: =BK32+BJ32-BD32 -> 384 | BM32: 1268 | BO32: =BN32+BM32-BJ32 -> 378 | BP32: 52 | BQ32: 1581 | BR32: =BQ32+BP32-BM32 -> 365 | BS32: 426 | BU32: =BT32+BS32-BP32 -> 374 | BV32: 804 | BX32: =BW32+BV32-BS32 -> 378 | BY32: 1151 | CA32: =BZ32+BY32-BV32 -> 347 | CE32: 1522 | CG32: =CF32+CE32-BY32 -> 371 | CH32: 337 | CI32: 1560 | CJ32: =CI32+CH32-CE32 -> 375 | CK32: 704 | CM32: =CL32+CK32-CH32 -> 367 | CN32: 1078 | CP32: =CO32+CN32-CK32 -> 374 | CQ32: 1449 | CS32: =CR32+CQ32-CN32 -> 371 | CT32: 0 | CU32: 1588 | CV32: =CU32+CT32-CQ32 -> 139 | CZ32: 0 | DB32: =DA32+CZ32-CT32 -> 0 | DC32: 340 | DE32: =DD32+DC32-CZ32 -> 340 | DF32: 716 | DH32: =DG32+DF32-DC32 -> 376 | DI32: 1074 | DK32: =DJ32+DI32-DF32 -> 358 | DL32: 311 | DM32: 1133 | DN32: =DM32+DL32-DI32 -> 370 | DO32: 640 | DQ32: =DP32+DO32-DL32 -> 329
A33: 29 | B33: 0 | C33: 1359 | D33: 323 | E33: SC-1020 | F33: SC-1020 | G33: SC-1020 | H33: SC-1020 | I33: SC-1020 | J33: SC-1020 | K33: SC-1020 | L33: SC-1020 | M33: SC-1020 | N33: SC-1020 | O33: SC-1020 | P33: SC-1020 | Q33: SC-1020 | R33: SC-1020 | S33: SC-1020 | T33: SC-1020 | U33: SC-1020 | V33: SC-1020 | W33: SC-1020 | X33: SC-1020 | Y33: SC-1020 | Z33: SC-1020 | AA33: SC-1020 | AB33: SC-1020 | AC33: SC-1020 | AD33: SC-1020 | AE33: SC-1020 | AF33: 339 | AH33: =AG33+AF33-B33 -> 339 | AI33: 687 | AK33: =AJ33+AI33-AF33 -> 348 | AO33: 1054 | AQ33: =AP33+AO33-AI33 -> 367 | AR33: 1422 | AT33: =AS33+AR33-AO33 -> 368 | AU33: 303 | AV33: 1475 | AW33: =AV33+AU33-AR33 -> 356 | AX33: 682 | AZ33: =AY33+AX33-AU33 -> 379 | BA33: 1056 | BC33: =BB33+BA33-AX33 -> 374 | BD33: 1427 | BF33: =BE33+BD33-BA33 -> 371 | BJ33: 248 | BK33: 1560 | BL33: =BK33+BJ33-BD33 -> 381 | BM33: 624 | BO33: =BN33+BM33-BJ33 -> 376 | BP33: 1008 | BR33: =BQ33+BP33-BM33 -> 384 | BS33: 1377 | BU33: =BT33+BS33-BP33 -> 369 | BV33: 190 | BW33: 1560 | BX33: =BW33+BV33-BS33 -> 373 | BY33: 547 | CA33: =BZ33+BY33-BV33 -> 357 | CE33: 235 | CF33: 682 | CG33: =CF33+CE33-BY33 -> 370 | CH33: 609 | CJ33: =CI33+CH33-CE33 -> 374 | CK33: 362 | CL33: 612 | CM33: =CL33+CK33-CH33 -> 365 | CN33: 739 | CP33: =CO33+CN33-CK33 -> 377 | CQ33: 1106 | CS33: =CR33+CQ33-CN33 -> 367 | CT33: 1454 | CV33: =CU33+CT33-CQ33 -> 348 | CZ33: 267 | DA33: 1560 | DB33: =DA33+CZ33-CT33 -> 373 | DC33: 0 | DD33: 413 | DE33: =DD33+DC33-CZ33 -> 146 | DF33: 294 | DH33: =DG33+DF33-DC33 -> 294 | DI33: 660 | DK33: =DJ33+DI33-DF33 -> 366 | DL33: 338 | DM33: 677 | DN33: =DM33+DL33-DI33 -> 355 | DO33: 653 | DQ33: =DP33+DO33-DL33 -> 315
A34: 30 | B34: 355 | C34: 1516 | D34: 365 | E34: SC-1020 | F34: SC-1020 | G34: SC-1020 | H34: SC-1020 | I34: SC-1020 | J34: SC-1020 | K34: SC-1020 | L34: SC-1020 | M34: SC-1020 | N34: SC-1020 | O34: SC-1020 | P34: SC-1020 | Q34: SC-1020 | R34: SC-1020 | S34: SC-1020 | T34: SC-1020 | U34: SC-1020 | V34: 011-4 | W34: 011-4 | X34: 011-4 | Y34: 011-4 | Z34: 011-4 | AA34: 011-4 | AB34: 011-4 | AC34: 011-4 | AD34: 011-4 | AE34: 011-4 | AF34: 725 | AH34: =AG34+AF34-B34 -> 370 | AI34: 1081 | AK34: =AJ34+AI34-AF34 -> 356 | AO34: 1 | AP34: 1454 | AQ34: =AP34+AO34-AI34 -> 374 | AR34: 364 | AT34: =AS34+AR34-AO34 -> 363 | AU34: 722 | AW34: =AV34+AU34-AR34 -> 358 | AX34: 40 | AY34: 1061 | AZ34: =AY34+AX34-AU34 -> 379 | BA34: 371 | BC34: =BB34+BA34-AX34 -> 331 | BD34: 725 | BF34: =BE34+BD34-BA34 -> 354 | BJ34: 1083 | BL34: =BK34+BJ34-BD34 -> 358 | BM34: 1449 | BO34: =BN34+BM34-BJ34 -> 366 | BP34: 266 | BQ34: 1560 | BR34: =BQ34+BP34-BM34 -> 377 | BS34: 628 | BU34: =BT34+BS34-BP34 -> 362 | BV34: 1005 | BX34: =BW34+BV34-BS34 -> 377 | BY34: 1361 | CA34: =BZ34+BY34-BV34 -> 356 | CE34: 267 | CF34: 1459 | CG34: =CF34+CE34-BY34 -> 365 | CH34: 563 | CJ34: =CI34+CH34-CE34 -> 296 | CK34: 248 | CL34: 676 | CM34: =CL34+CK34-CH34 -> 361 | CN34: 616 | CP34: =CO34+CN34-CK34 -> 368 | CQ34: 990 | CS34: =CR34+CQ34-CN34 -> 374 | CT34: 1329 | CV34: =CU34+CT34-CQ34 -> 339 | CZ34: 144 | DA34: 1560 | DB34: =DA34+CZ34-CT34 -> 375 | DC34: 506 | DE34: =DD34+DC34-CZ34 -> 362 | DF34: 124 | DG34: 749 | DH34: =DG34+DF34-DC34 -> 367 | DI34: 482 | DK34: =DJ34+DI34-DF34 -> 358 | DL34: 836 | DN34: =DM34+DL34-DI34 -> 354 | DO34: 1174 | DQ34: =DP34+DO34-DL34 -> 338
A35: 31 | B35: 542 | D35: 328 | E35: ABZ85,DR794Z,DR856Z | F35: ABZ85,DR794Z,DR856Z | G35: ABZ85,DR794Z,DR856Z | H35: DR1073Z,DR856Z | I35: DR1073Z,DR856Z | J35: DR1073Z,DR856Z | K35: DR1073Z,DR856Z | L35: DR1073Z,DR856Z | M35: DR1073Z,DR856Z | N35: SC-1020 | O35: SC-1020 | P35: SC-1020 | Q35: SC-1020 | R35: SC-1020 | S35: SC-1020 | T35: SC-1020 | U35: SC-1020 | V35: SC-1020 | W35: SC-1020 | X35: SC-1020 | Y35: SC-1020 | Z35: SC-1020 | AA35: SC-1020 | AB35: SC-1020 | AC35: SC-1020 | AD35: SC-1020 | AE35: SC-1020 | AF35: 891 | AH35: =AG35+AF35-B35 -> 349 | AI35: 1220 | AK35: =AJ35+AI35-AF35 -> 329 | AO35: 249 | AP35: 1273 | AQ35: =AP35+AO35-AI35 -> 302 | AR35: 592 | AT35: =AS35+AR35-AO35 -> 343 | AU35: 910 | AW35: =AV35+AU35-AR35 -> 318 | AX35: 58 | AY35: 1200 | AZ35: =AY35+AX35-AU35 -> 348 | BA35: 394 | BC35: =BB35+BA35-AX35 -> 336 | BD35: 0 | BE35: 394 | BF35: =BE35+BD35-BA35 -> 0 | BJ35: 0 | BL35: =BK35+BJ35-BD35 -> 0 | BM35: 0 | BO35: =BN35+BM35-BJ35 -> 0 | BP35: 282 | BR35: =BQ35+BP35-BM35 -> 282 | BS35: 656 | BU35: =BT35+BS35-BP35 -> 374 | BV35: 1028 | BX35: =BW35+BV35-BS35 -> 372 | BY35: 292 | BZ35: 1084 | CA35: =BZ35+BY35-BV35 -> 348 | CE35: =366+292 -> 658 | CG35: =CF35+CE35-BY35 -> 366 | CH35: =729+292 -> 1021 | CJ35: =CI35+CH35-CE35 -> 363 | CK35: =933+292 -> 1225 | CM35: =CL35+CK35-CH35 -> 204 | CN35: 31 | CO35: 1560 | CP35: =CO35+CN35-CK35 -> 366 | CQ35: 398 | CS35: =CR35+CQ35-CN35 -> 367 | CT35: 742 | CV35: =CU35+CT35-CQ35 -> 344 | CZ35: 1109 | DB35: =DA35+CZ35-CT35 -> 367 | DC35: 1473 | DE35: =DD35+DC35-CZ35 -> 364 | DF35: 1837 | DH35: =DG35+DF35-DC35 -> 364 | DI35: 0 | DJ35: 2163 | DK35: =DJ35+DI35-DF35 -> 326 | DL35: 331 | DN35: =DM35+DL35-DI35 -> 331 | DO35: 658 | DQ35: =DP35+DO35-DL35 -> 327
A36: 32 | B36: 0 | C36: 677 | D36: 241 | E36: ABZ85,DR794Z,DR856Z | F36: DR1073Z,DR856Z | G36: DR1073Z,DR856Z | H36: DR1073Z,DR856Z | I36: DR1073Z,DR856Z | J36: DR1073Z,DR856Z | K36: DR1073Z,DR856Z | L36: DR1073Z,DR856Z | M36: DR1073Z,DR856Z | N36: SC-1020 | O36: SC-1020 | P36: SC-1020 | Q36: SC-1020 | R36: SC-1020 | S36: SC-1020 | T36: SC-1020 | U36: SC-1020 | V36: SC-1020 | W36: SC-1020 | X36: SC-1020 | Y36: SC-1020 | Z36: SC-1020 | AA36: SC-1020 | AB36: SC-1020 | AC36: SC-1020 | AD36: SC-1020 | AE36: SC-1020 | AF36: 335 | AH36: =AG36+AF36-B36 -> 335 | AI36: 665 | AK36: =AJ36+AI36-AF36 -> 330 | AO36: 1011 | AQ36: =AP36+AO36-AI36 -> 346 | AR36: 158 | AS36: 1200 | AT36: =AS36+AR36-AO36 -> 347 | AU36: 504 | AW36: =AV36+AU36-AR36 -> 346 | AX36: 845 | AZ36: =AY36+AX36-AU36 -> 341 | BA36: 944 | BC36: =BB36+BA36-AX36 -> 99 | BD36: 0 | BE36: 944 | BF36: =BE36+BD36-BA36 -> 0 | BJ36: 0 | BL36: =BK36+BJ36-BD36 -> 0 | BM36: 0 | BO36: =BN36+BM36-BJ36 -> 0 | BP36: 293 | BR36: =BQ36+BP36-BM36 -> 293 | BS36: 676 | BU36: =BT36+BS36-BP36 -> 383 | BV36: 1044 | BX36: =BW36+BV36-BS36 -> 368 | BY36: 1401 | CA36: =BZ36+BY36-BV36 -> 357 | CE36: 206 | CF36: 1570 | CG36: =CF36+CE36-BY36 -> 375 | CH36: 573 | CJ36: =CI36+CH36-CE36 -> 367 | CK36: 946 | CM36: =CL36+CK36-CH36 -> 373 | CN36: 1311 | CP36: =CO36+CN36-CK36 -> 365 | CQ36: 234 | CR36: 1448 | CS36: =CR36+CQ36-CN36 -> 371 | CT36: 588 | CV36: =CU36+CT36-CQ36 -> 354 | CZ36: 966 | DB36: =DA36+CZ36-CT36 -> 378 | DC36: 0 | DD36: 1195 | DE36: =DD36+DC36-CZ36 -> 229 | DF36: 322 | DH36: =DG36+DF36-DC36 -> 322 | DI36: 682 | DK36: =DJ36+DI36-DF36 -> 360 | DL36: 1055 | DN36: =DM36+DL36-DI36 -> 373 | DO36: 1394 | DQ36: =DP36+DO36-DL36 -> 339
A37: 33 | B37: 316 | C37: 1560 | D37: 406 | E37: 011-3 61" | F37: 011-3 | G37: 011-3 | H37: 011-3 | I37: 011-3 | J37: 011-3 | K37: 011-3 | L37: 011-3 | M37: 011-3 | N37: 011-3 | O37: 011-3 | P37: 011-3 | Q37: 011-3 | R37: 011-3 | S37: 011-3 | T37: 011-3 | U37: 011-3 | V37: 011-3 | W37: 011-3 | X37: 011-3 | Y37: 011-3 | Z37: 011-3 | AA37: SC-1020 | AB37: SC-1020 | AC37: SC-1020 | AD37: SC-1020 | AE37: SC-1020 | AF37: 217 | AG37: 447 | AH37: =AG37+AF37-B37 -> 348 | AI37: 598 | AK37: =AJ37+AI37-AF37 -> 381 | AO37: 980 | AQ37: =AP37+AO37-AI37 -> 382 | AR37: =1380*0.9144 -> 1261.872 | AT37: =AS37+AR37-AO37 -> 281.872 | AU37: 70 | AV37: 1560 | AW37: =AV37+AU37-AR37 -> 368.128 | AX37: 429 | AZ37: =AY37+AX37-AU37 -> 359 | BA37: 785 | BC37: =BB37+BA37-AX37 -> 356 | BD37: 1146 | BF37: =BE37+BD37-BA37 -> 361 | BJ37: 1514 | BL37: =BK37+BJ37-BD37 -> 368 | BM37: 327 | BN37: 1560 | BO37: =BN37+BM37-BJ37 -> 373 | BP37: 676 | BR37: =BQ37+BP37-BM37 -> 349 | BS37: 1038 | BU37: =BT37+BS37-BP37 -> 362 | BV37: 213 | BW37: 1180 | BX37: =BW37+BV37-BS37 -> 355 | BY37: 556 | CA37: =BZ37+BY37-BV37 -> 343 | CE37: 911 | CG37: =CF37+CE37-BY37 -> 355 | CH37: 1273 | CJ37: =CI37+CH37-CE37 -> 362 | CK37: 57 | CL37: 1560 | CM37: =CL37+CK37-CH37 -> 344 | CN37: 426 | CP37: =CO37+CN37-CK37 -> 369 | CQ37: 787 | CS37: =CR37+CQ37-CN37 -> 361 | CT37: 162 | CU37: 966 | CV37: =CU37+CT37-CQ37 -> 341 | CZ37: 0 | DA37: =359+136 -> 495 | DB37: =DA37+CZ37-CT37 -> 333 | DC37: 244 | DE37: =DD37+DC37-CZ37 -> 244 | DF37: 616 | DH37: =DG37+DF37-DC37 -> 372 | DI37: 976 | DK37: =DJ37+DI37-DF37 -> 360 | DL37: 1338 | DN37: =DM37+DL37-DI37 -> 362 | DO37: 81 | DP37: 1560 | DQ37: =DP37+DO37-DL37 -> 303
A38: 34 | B38: 767 | D38: 405 | E38: 011-3 61" | F38: 011-3 | G38: 011-3 | H38: 011-3 | I38: 011-3 | J38: 011-3 | K38: 011-3 | L38: 011-3 | M38: 011-3 | N38: 011-3 | O38: 011-3 | P38: 011-3 | Q38: 011-3 | R38: 011-3 | S38: 011-3 | T38: 011-3 | U38: 011-3 | V38: 011-3 | W38: 011-3 | X38: 011-3 | Y38: 011-3 | Z38: 011-3 | AA38: 011-3 | AB38: SC-1020 | AC38: SC-1020 | AD38: SC-1020 | AE38: SC-1020 | AF38: 287 | AG38: 862 | AH38: =AG38+AF38-B38 -> 382 | AI38: 678 | AK38: =AJ38+AI38-AF38 -> 391 | AO38: 1084 | AQ38: =AP38+AO38-AI38 -> 406 | AR38: =1489*0.9144 -> 1361.5416 | AT38: =AS38+AR38-AO38 -> 277.5416 | AU38: 165 | AV38: 1560 | AW38: =AV38+AU38-AR38 -> 363.4584 | AX38: 543 | AZ38: =AY38+AX38-AU38 -> 378 | BA38: 918 | BC38: =BB38+BA38-AX38 -> 375 | BD38: 1283 | BF38: =BE38+BD38-BA38 -> 365 | BJ38: 94 | BK38: 1560 | BL38: =BK38+BJ38-BD38 -> 371 | BM38: 466 | BO38: =BN38+BM38-BJ38 -> 372 | BP38: 842 | BR38: =BQ38+BP38-BM38 -> 376 | BS38: 131 | BT38: 1080 | BU38: =BT38+BS38-BP38 -> 369 | BV38: 476 | BX38: =BW38+BV38-BS38 -> 345 | BY38: 822 | CA38: =BZ38+BY38-BV38 -> 346 | CE38: 1194 | CG38: =CF38+CE38-BY38 -> 372 | CH38: 2 | CI38: 1560 | CJ38: =CI38+CH38-CE38 -> 368 | CK38: 373 | CM38: =CL38+CK38-CH38 -> 371 | CN38: 702 | CP38: =CO38+CN38-CK38 -> 329 | CQ38: 1070 | CS38: =CR38+CQ38-CN38 -> 368 | CT38: 1410 | CV38: =CU38+CT38-CQ38 -> 340 | CZ38: 217 | DA38: 1560 | DB38: =DA38+CZ38-CT38 -> 367 | DC38: 0 | DD38: 495 | DE38: =DD38+DC38-CZ38 -> 278 | DF38: 310 | DH38: =DG38+DF38-DC38 -> 310 | DI38: 678 | DK38: =DJ38+DI38-DF38 -> 368 | DL38: 1043 | DN38: =DM38+DL38-DI38 -> 365 | DO38: 1372 | DQ38: =DP38+DO38-DL38 -> 329
A39: 35 | B39: 97 | C39: 1560 | D39: 373 | E39: SC-1020 | F39: SC-1020 | G39: SC-1020 | H39: SC-1020 | I39: SC-1020 | J39: SC-1020 | K39: SC-1020 | L39: SC-1020 | M39: SC-1020 | N39: 011-3 | O39: 011-3 | P39: 011-3 | Q39: 011-3 | R39: SC-1020 | S39: SC-1020 | T39: SC-1020 | U39: SC-1020 | V39: SC-1020 | W39: SC-1020 | X39: SC-1020 | Y39: SC-1020 | Z39: SC-1020 | AA39: SC-1020 | AB39: SC-1020 | AC39: SC-1020 | AD39: SC-1020 | AE39: SC-1020 | AF39: 479 | AH39: =AG39+AF39-B39 -> 382 | AI39: 831 | AK39: =AJ39+AI39-AF39 -> 352 | AO39: 1214 | AQ39: =AP39+AO39-AI39 -> 383 | AR39: 23 | AS39: 1560 | AT39: =AS39+AR39-AO39 -> 369 | AU39: 395 | AW39: =AV39+AU39-AR39 -> 372 | AX39: 398 | AZ39: =AY39+AX39-AU39 -> 3 | BA39: 0 | BB39: 675 | BC39: =BB39+BA39-AX39 -> 277 | BD39: 0 | BF39: =BE39+BD39-BA39 -> 0 | BJ39: 319 | BL39: =BK39+BJ39-BD39 -> 319 | BM39: 682 | BO39: =BN39+BM39-BJ39 -> 363 | BP39: 1063 | BR39: =BQ39+BP39-BM39 -> 381 | BS39: 1444 | BU39: =BT39+BS39-BP39 -> 381 | BV39: 354 | BW39: 1445 | BX39: =BW39+BV39-BS39 -> 355 | BY39: 717 | CA39: =BZ39+BY39-BV39 -> 363 | CE39: 1088 | CG39: =CF39+CE39-BY39 -> 371 | CH39: 42 | CI39: 1408 | CJ39: =CI39+CH39-CE39 -> 362 | CK39: 416 | CM39: =CL39+CK39-CH39 -> 374 | CN39: 787 | CP39: =CO39+CN39-CK39 -> 371 | CQ39: 1161 | CS39: =CR39+CQ39-CN39 -> 374 | CT39: 15 | CU39: 1504 | CV39: =CU39+CT39-CQ39 -> 358 | CZ39: 394 | DB39: =DA39+CZ39-CT39 -> 379 | DC39: 0 | DD39: 555 | DE39: =DD39+DC39-CZ39 -> 161 | DF39: 293 | DH39: =DG39+DF39-DC39 -> 293 | DI39: 664 | DK39: =DJ39+DI39-DF39 -> 371 | DL39: 57 | DM39: 960 | DN39: =DM39+DL39-DI39 -> 353 | DO39: 398 | DQ39: =DP39+DO39-DL39 -> 341
